Workbook

Sheet SUMMARY
B2: =_xlfn.CONCAT("DAILY SUMMARY ",TEXT(B4,"dd-mmm-yy")) -> DAILY SUMMARY 29-Jul-26
B4: 46232 | C4: ← enter date here
B6: QTY (ton) | C6: =SUMIFS('Daily Ledger'!$F:$F,'Daily Ledger'!$A:$A,$B$4) -> 956.18
B7: Crusher Amount (₹) | C7: =SUMIFS('Daily Ledger'!$K:$K,'Daily Ledger'!$A:$A,$B$4) -> 778095.65
B8: SUN Quary Amount (₹) | C8: =SUMIFS('Daily Ledger'!$L:$L,'Daily Ledger'!$A:$A,$B$4) -> 607070
B9: Vehicle Rent (₹) | C9: =SUMIFS('Daily Ledger'!$O:$O,'Daily Ledger'!$A:$A,$B$4) -> 137756.05
B10: Pass QTY | C10: =SUMIFS('Daily Ledger'!$AQ:$AQ,'Daily Ledger'!$A:$A,$B$4) -> 603.13
B11: Pass Profit | C11: =SUMIFS('Daily Ledger'!$AR:$AR,'Daily Ledger'!$A:$A,$B$4) -> 13879.35
B12: WO Pass QTY | C12: =SUMIFS('Daily Ledger'!$AS:$AS,'Daily Ledger'!$A:$A,$B$4) -> 353.05
B13: WO Pass Profit | C13: =SUMIFS('Daily Ledger'!$AT:$AT,'Daily Ledger'!$A:$A,$B$4) -> 19390.25
B14: Monthly Discount qty | C14: =SUMIFS('Daily Ledger'!$AU:$AU,'Daily Ledger'!$A:$A,$B$4) -> 386.58
B15: Monthly Discount (₹) | C15: =SUMIFS('Daily Ledger'!$AV:$AV,'Daily Ledger'!$A:$A,$B$4) -> 7731.6
B17: Crusher | C17: Amount (₹) | D17: Quantity (Ton)
B18: Outside site No Profit | C18: =SUMIFS('Daily Ledger'!$K:$K,'Daily Ledger'!$A:$A,$B$4,'Daily Ledger'!$C:$C,$B18) -> 0 | D18: =SUMIFS('Daily Ledger'!$F:$F,'Daily Ledger'!$A:$A,$B$4,'Daily Ledger'!$C:$C,$B18) -> 0
B19: MR Granites | C19: =SUMIFS('Daily Ledger'!$K:$K,'Daily Ledger'!$A:$A,$B$4,'Daily Ledger'!$C:$C,$B19) -> 112650.75 | D19: =SUMIFS('Daily Ledger'!$F:$F,'Daily Ledger'!$A:$A,$B$4,'Daily Ledger'!$C:$C,$B19) -> 166.89
B20: AVK | C20: =SUMIFS('Daily Ledger'!$K:$K,'Daily Ledger'!$A:$A,$B$4,'Daily Ledger'!$C:$C,$B20) -> 250083 | D20: =SUMIFS('Daily Ledger'!$F:$F,'Daily Ledger'!$A:$A,$B$4,'Daily Ledger'!$C:$C,$B20) -> 277.87
B21: AM Crusher | C21: =SUMIFS('Daily Ledger'!$K:$K,'Daily Ledger'!$A:$A,$B$4,'Daily Ledger'!$C:$C,$B21) -> 0 | D21: =SUMIFS('Daily Ledger'!$F:$F,'Daily Ledger'!$A:$A,$B$4,'Daily Ledger'!$C:$C,$B21) -> 0
B22: Al Falah metal crusher | C22: =SUMIFS('Daily Ledger'!$K:$K,'Daily Ledger'!$A:$A,$B$4,'Daily Ledger'!$C:$C,$B22) -> 168884.4 | D22: =SUMIFS('Daily Ledger'!$F:$F,'Daily Ledger'!$A:$A,$B$4,'Daily Ledger'!$C:$C,$B22) -> 194.12
B23: Desinganad crusher | C23: =SUMIFS('Daily Ledger'!$K:$K,'Daily Ledger'!$A:$A,$B$4,'Daily Ledger'!$C:$C,$B23) -> 141312.5 | D23: =SUMIFS('Daily Ledger'!$F:$F,'Daily Ledger'!$A:$A,$B$4,'Daily Ledger'!$C:$C,$B23) -> 161.5
B24: Desinganad MR own crusher | C24: =SUMIFS('Daily Ledger'!$K:$K,'Daily Ledger'!$A:$A,$B$4,'Daily Ledger'!$C:$C,$B24) -> 57192.75 | D24: =SUMIFS('Daily Ledger'!$F:$F,'Daily Ledger'!$A:$A,$B$4,'Daily Ledger'!$C:$C,$B24) -> 84.73
B25: Mavila crusher | C25: =SUMIFS('Daily Ledger'!$K:$K,'Daily Ledger'!$A:$A,$B$4,'Daily Ledger'!$C:$C,$B25) -> 0 | D25: =SUMIFS('Daily Ledger'!$F:$F,'Daily Ledger'!$A:$A,$B$4,'Daily Ledger'!$C:$C,$B25) -> 0
B26: Thangalathu Crusher | C26: =SUMIFS('Daily Ledger'!$K:$K,'Daily Ledger'!$A:$A,$B$4,'Daily Ledger'!$C:$C,$B26) -> 0 | D26: =SUMIFS('Daily Ledger'!$F:$F,'Daily Ledger'!$A:$A,$B$4,'Daily Ledger'!$C:$C,$B26) -> 0
B27: Arun Kaavuvila | C27: =SUMIFS('Daily Ledger'!$K:$K,'Daily Ledger'!$A:$A,$B$4,'Daily Ledger'!$C:$C,$B27) -> 0 | D27: =SUMIFS('Daily Ledger'!$F:$F,'Daily Ledger'!$A:$A,$B$4,'Daily Ledger'!$C:$C,$B27) -> 0
B28: Police Mahesh | C28: =SUMIFS('Daily Ledger'!$K:$K,'Daily Ledger'!$A:$A,$B$4,'Daily Ledger'!$C:$C,$B28) -> 0 | D28: =SUMIFS('Daily Ledger'!$F:$F,'Daily Ledger'!$A:$A,$B$4,'Daily Ledger'!$C:$C,$B28) -> 0
B29: MR Oyoor | C29: =SUMIFS('Daily Ledger'!$K:$K,'Daily Ledger'!$A:$A,$B$4,'Daily Ledger'!$C:$C,$B29) -> 47972.25 | D29: =SUMIFS('Daily Ledger'!$F:$F,'Daily Ledger'!$A:$A,$B$4,'Daily Ledger'!$C:$C,$B29) -> 71.07
... B31: Kochammini | C31: =SUMIFS('Daily Ledger'!$K:$K,'Daily Ledger'!$A:$A,$B$4,'Daily Ledger'!$C:$C,$B31) -> 0 | D31: =SUMIFS('Daily Ledger'!$F:$F,'Daily Ledger'!$A:$A,$B$4,'Daily Ledger'!$C:$C,$B31) -> 0

Sheet Vehicle Rent
B2: =_xlfn.CONCAT("VEHICLE RENT ",TEXT(B4,"dd-mmm-yy")) -> VEHICLE RENT 29-Jul-26
B4: 46232 | C4: ← enter date here
B6: Vehicle Number | C6: Owner Name | D6: Trips | E6: Total Qty (ton) | F6: Total Rent (₹)
B7: KL 05 AS 7477 | C7: =IFERROR(VLOOKUP($B7,Legend!$B$20:$C$126,2,FALSE()),"") -> Sooraj | D7: =COUNTIFS('Daily Ledger'!$M:$M,$B7,'Daily Ledger'!$A:$A,$B$4) -> 1 | E7: =SUMIFS('Daily Ledger'!$F:$F,'Daily Ledger'!$M:$M,$B7,'Daily Ledger'!$A:$A,$B$4) -> 33.53 | F7: =SUMIFS('Daily Ledger'!$O:$O,'Daily Ledger'!$M:$M,$B7,'Daily Ledger'!$A:$A,$B$4) -> 7208.95
B8: KL 02 BG 3968 | C8: =IFERROR(VLOOKUP($B8,Legend!$B$20:$C$126,2,FALSE()),"") -> Police | D8: =COUNTIFS('Daily Ledger'!$M:$M,$B8,'Daily Ledger'!$A:$A,$B$4) -> 0 | E8: =SUMIFS('Daily Ledger'!$F:$F,'Daily Ledger'!$M:$M,$B8,'Daily Ledger'!$A:$A,$B$4) -> 0 | F8: =SUMIFS('Daily Ledger'!$O:$O,'Daily Ledger'!$M:$M,$B8,'Daily Ledger'!$A:$A,$B$4) -> 0
B9: KL 21 U 5340 | C9: =IFERROR(VLOOKUP($B9,Legend!$B$20:$C$126,2,FALSE()),"") -> Arun 5340 | D9: =COUNTIFS('Daily Ledger'!$M:$M,$B9,'Daily Ledger'!$A:$A,$B$4) -> 0 | E9: =SUMIFS('Daily Ledger'!$F:$F,'Daily Ledger'!$M:$M,$B9,'Daily Ledger'!$A:$A,$B$4) -> 0 | F9: =SUMIFS('Daily Ledger'!$O:$O,'Daily Ledger'!$M:$M,$B9,'Daily Ledger'!$A:$A,$B$4) -> 0
B10: KL 40 Q 3885 | C10: =IFERROR(VLOOKUP($B10,Legend!$B$20:$C$126,2,FALSE()),"") -> Achu 3885 | D10: =COUNTIFS('Daily Ledger'!$M:$M,$B10,'Daily Ledger'!$A:$A,$B$4) -> 0 | E10: =SUMIFS('Daily Ledger'!$F:$F,'Daily Ledger'!$M:$M,$B10,'Daily Ledger'!$A:$A,$B$4) -> 0 | F10: =SUMIFS('Daily Ledger'!$O:$O,'Daily Ledger'!$M:$M,$B10,'Daily Ledger'!$A:$A,$B$4) -> 0
B11: Kl 25 Q 5299 | C11: =IFERROR(VLOOKUP($B11,Legend!$B$20:$C$126,2,FALSE()),"") -> Kochammini own | D11: =COUNTIFS('Daily Ledger'!$M:$M,$B11,'Daily Ledger'!$A:$A,$B$4) -> 0 | E11: =SUMIFS('Daily Ledger'!$F:$F,'Daily Ledger'!$M:$M,$B11,'Daily Ledger'!$A:$A,$B$4) -> 0 | F11: =SUMIFS('Daily Ledger'!$O:$O,'Daily Ledger'!$M:$M,$B11,'Daily Ledger'!$A:$A,$B$4) -> 0
B12: KL 07 CP 9255 | C12: =IFERROR(VLOOKUP($B12,Legend!$B$20:$C$126,2,FALSE()),"") -> Ajin Rameshan | D12: =COUNTIFS('Daily Ledger'!$M:$M,$B12,'Daily Ledger'!$A:$A,$B$4) -> 2 | E12: =SUMIFS('Daily Ledger'!$F:$F,'Daily Ledger'!$M:$M,$B12,'Daily Ledger'!$A:$A,$B$4) -> 61.38 | F12: =SUMIFS('Daily Ledger'!$O:$O,'Daily Ledger'!$M:$M,$B12,'Daily Ledger'!$A:$A,$B$4) -> 13196.5
B13: Kl 40 H 4079 | C13: =IFERROR(VLOOKUP($B13,Legend!$B$20:$C$126,2,FALSE()),"") -> Police | D13: =COUNTIFS('Daily Ledger'!$M:$M,$B13,'Daily Ledger'!$A:$A,$B$4) -> 0 | E13: =SUMIFS('Daily Ledger'!$F:$F,'Daily Ledger'!$M:$M,$B13,'Daily Ledger'!$A:$A,$B$4) -> 0 | F13: =SUMIFS('Daily Ledger'!$O:$O,'Daily Ledger'!$M:$M,$B13,'Daily Ledger'!$A:$A,$B$4) -> 0
B14: KL 14 AA 3499 | C14: =IFERROR(VLOOKUP($B14,Legend!$B$20:$C$126,2,FALSE()),"") -> ANI AVK | D14: =COUNTIFS('Daily Ledger'!$M:$M,$B14,'Daily Ledger'!$A:$A,$B$4) -> 2 | E14: =SUMIFS('Daily Ledger'!$F:$F,'Daily Ledger'!$M:$M,$B14,'Daily Ledger'!$A:$A,$B$4) -> 66.79 | F14: =SUMIFS('Daily Ledger'!$O:$O,'Daily Ledger'!$M:$M,$B14,'Daily Ledger'!$A:$A,$B$4) -> 15027.75
B15: KL 05 AL 8530 | C15: =IFERROR(VLOOKUP($B15,Legend!$B$20:$C$126,2,FALSE()),"") | D15: =COUNTIFS('Daily Ledger'!$M:$M,$B15,'Daily Ledger'!$A:$A,$B$4) -> 0 | E15: =SUMIFS('Daily Ledger'!$F:$F,'Daily Ledger'!$M:$M,$B15,'Daily Ledger'!$A:$A,$B$4) -> 0 | F15: =SUMIFS('Daily Ledger'!$O:$O,'Daily Ledger'!$M:$M,$B15,'Daily Ledger'!$A:$A,$B$4) -> 0
B16: KL 26 F 9304 | C16: =IFERROR(VLOOKUP($B16,Legend!$B$20:$C$126,2,FALSE()),"") | D16: =COUNTIFS('Daily Ledger'!$M:$M,$B16,'Daily Ledger'!$A:$A,$B$4) -> 0 | E16: =SUMIFS('Daily Ledger'!$F:$F,'Daily Ledger'!$M:$M,$B16,'Daily Ledger'!$A:$A,$B$4) -> 0 | F16: =SUMIFS('Daily Ledger'!$O:$O,'Daily Ledger'!$M:$M,$B16,'Daily Ledger'!$A:$A,$B$4) -> 0
B17: KL 02 BS 9636 | C17: =IFERROR(VLOOKUP($B17,Legend!$B$20:$C$126,2,FALSE()),"") | D17: =COUNTIFS('Daily Ledger'!$M:$M,$B17,'Daily Ledger'!$A:$A,$B$4) -> 0 | E17: =SUMIFS('Daily Ledger'!$F:$F,'Daily Ledger'!$M:$M,$B17,'Daily Ledger'!$A:$A,$B$4) -> 0 | F17: =SUMIFS('Daily Ledger'!$O:$O,'Daily Ledger'!$M:$M,$B17,'Daily Ledger'!$A:$A,$B$4) -> 0
B18: KL 23 R 832 | C18: =IFERROR(VLOOKUP($B18,Legend!$B$20:$C$126,2,FALSE()),"") | D18: =COUNTIFS('Daily Ledger'!$M:$M,$B18,'Daily Ledger'!$A:$A,$B$4) -> 0 | E18: =SUMIFS('Daily Ledger'!$F:$F,'Daily Ledger'!$M:$M,$B18,'Daily Ledger'!$A:$A,$B$4) -> 0 | F18: =SUMIFS('Daily Ledger'!$O:$O,'Daily Ledger'!$M:$M,$B18,'Daily Ledger'!$A:$A,$B$4) -> 0
... B34: KL 16 Y 6260 | C34: =IFERROR(VLOOKUP($B34,Legend!$B$20:$C$126,2,FALSE()),"") | D34: =COUNTIFS('Daily Ledger'!$M:$M,$B34,'Daily Ledger'!$A:$A,$B$4) -> 1 | E34: =SUMIFS('Daily Ledger'!$F:$F,'Daily Ledger'!$M:$M,$B34,'Daily Ledger'!$A:$A,$B$4) -> 31.9 | F34: =SUMIFS('Daily Ledger'!$O:$O,'Daily Ledger'!$M:$M,$B34,'Daily Ledger'!$A:$A,$B$4) -> 6858.5
B35: Total | D35: =SUM(D7:D34) -> 32 | E35: =SUM(E7:E34) -> 956.18 | F35: =SUM(F7:F34) -> 137756.05

Sheet Legend
B1: Rate Chart | E1: Crusher | F1: Type | G1: Quary | H1: Vehicle Rent | I1: Crusher
B2: Fayas Monthly Discount | C2: 20 | E2: MR Granites | F2: Pass | G2: 650 | H2: 0 | I2: 675
E3: MR Granites | F3: WO Pass | G3: 610 | H3: 0 | I3: 675
E4: Kochammini | F4: Pass | G4: 640 | H4: 0 | I4: 645
E5: Kochammini | F5: WO Pass | G5: 610 | H5: 0 | I5: 645
E6: Mavila crusher | F6: Pass | G6: 640 | I6: 675
E7: Mavila crusher | F7: WO Pass | G7: 610 | H7: 0 | I7: 675
E8: Desinganad crusher | F8: Pass | G8: 650 | H8: 210 | I8: 875
E9: Desinganad crusher | F9: WO Pass | G9: 610 | H9: 210 | I9: 875
E10: Desinganad MR own crusher | F10: Pass | G10: 650 | I10: 675
E11: Desinganad MR own crusher | F11: WO Pass | G11: 610 | I11: 675
E12: Outside site No Profit | G12: 700 | I12: 700
E13: AVK | F13: Pass | G13: 650 | H13: 250 | I13: 900
E14: AVK | F14: WO Pass | G14: 610 | H14: 250 | I14: 900
E15: AM Crusher | F15: Pass | G15: 640 | H15: 220 | I15: 900
E16: Al Falah metal crusher | F16: Pass | G16: 640 | H16: 215 | I16: 870
E17: Al Falah metal crusher | F17: WO Pass | G17: 610 | H17: 215 | I17: 870
E18: Thangalathu Crusher | F18: Pass | G18: 640 | H18: 210 | I18: 850
B19: Vehicle Number | C19: Name | E19: Thangalathu Crusher | F19: WO Pass | G19: 610 | H19: 210 | I19: 850
B20: KL 21 U 5340 | C20: Arun 5340 | E20: Arun Kaavuvila | F20: Pass | G20: 640 | H20: 0 | I20: 700
B21: KL 05 AS 7477 | C21: Sooraj | E21: Arun Kaavuvila | F21: WO Pass | G21: 610 | H21: 0 | I21: 650
B22: KL 55 U 6040 | C22: Arun JP | E22: Police Mahesh | F22: Pass | G22: 640 | H22: 0 | I22: 650
B23: KL 37 C 6064 | C23: Prashanth | E23: Police Mahesh | F23: WO Pass | G23: 610 | H23: 0 | I23: 650
B24: KL 51 M 6466 | C24: Sreenandanam | E24: MR Oyoor | F24: Pass | G24: 640 | H24: 220 | I24: 900
B25: KL32T5450 | C25: Brittoli | E25: MR Oyoor | F25: WO Pass | G25: 610 | H25: 220 | I25: 900
B26: KL22T9318 | C26: Kulathinkara Own
B27: KL22U1246 | C27: Kulathinkara Own | E27: Note: Quary rates (Pass ₹650 / WO Pass ₹610) and crusher rates derived from the 29-Jul-26 ledger photos. Al Falah Pass rows used quary ₹640 that day.
B28: KL22T9364 | C28: Kulathinkara Own
B29: KL22T9297 | C29: Kulathinkara Own
B30: KL22T9334 | C30: Kulathinkara Own
B31: KL02BA4183 | C31: SS Own
B32: KL 02 BY 0313 | C32: SS Own
B33: KL 02 BD 8082 | C33: SS Own
B34: KL 33 M 2074 | C34: SS Own
B35: KL02BZ3326 | C35: SS Own
B36: KL 16 X 5898 | C36: Aju Ziyad
B37: KL 02 BG 3968 | C37: Police
B38: KL 04 AN 2804 | C38: Abhilash
B39: KL 16 T 4621 | C39: Abhilash
... B126: KL 05 AS 7477 | C126: Sooraj

Sheet Daily Ledger
P1: Outside site No Profit | Q1: MR Granites | S1: AVK | U1: AM Crusher | W1: Al Falah metal crusher | Y1: Desinganad crusher | AA1: Desinganad MR own crusher | AC1: Mavila crusher | AE1: Thangalathu Crusher | AG1: Arun Kaavuvila | AI1: Police Mahesh | AK1: MR Oyoor | AM1: Sooraj | AO1: Kochammini | AQ1: Pass | AS1: WO Pass
A2: Date | B2: Item Name | C2: Crusher | D2: Pass/with out pass | E2: Index Number | F2: QTY (ton) | G2: Quary Rate | H2: Crusher Rate | I2: Vehicle Rent rate | J2: Monthly Commission Rate | K2: Crusher Amount | L2: SUN Quary Amount (₹) | M2: Vehicle number | N2: Vehicle Ton | O2: Vehicle Rent | P2: Titan Rocks Old Crusher Amount (₹) | Q2: MR Granites Crusher Amount (₹) | R2: MR Granites Crusher Quantity (Ton) | S2: AVK Crusher Amount (₹) | T2: AVK Crusher Quantity (Ton) | U2: AM Crusher Crusher Amount (₹) | V2: AM Crusher Crusher Quantity (Ton) | W2: Al Falah metal crusher Crusher Amount (₹) | X2: Al Falah metal crusher Crusher Quantity (Ton) | Y2: Desinganad crusher Crusher Amount (₹) | Z2: Desinganad crusher Crusher Quantity (Ton) | AA2: Desinganad MR own crusher Crusher Amount (₹) | AB2: Desinganad MR own crusher Crusher Quantity (Ton) | AC2: Mavila crusher Crusher Amount (₹) | AD2: Mavila crusher Crusher Quantity (Ton) | AE2: Thangalathu Crusher Crusher Amount (₹) | AF2: Thangalathu Crusher Crusher Quantity (Ton) | AG2: Arun Kaavuvila Crusher Amount (₹) | AH2: Arun Kaavuvila Crusher Quantity (Ton) | AI2: Police Mahesh Crusher Amount (₹) | AJ2: Police Mahesh Crusher Quantity (Ton) | AK2: MR Oyoor Crusher Amount (₹) | AL2: MR Oyoor Crusher Quantity (Ton) | AM2: Sooraj Crusher Amount (₹) | AN2: Sooraj Crusher Quantity (Ton) | AO2: Kochammini Crusher Amount (₹) | AP2: Kochammini Crusher Quantity (Ton) | AQ2: Pass QTY | AR2: Pass Profit | AS2: WO Pass QTY | AT2: WO Pass Profit | AU2: Monthly Discount qty | AV2: Monthly Discount
A3: 45975 | B3: Rock | C3: Kochammini | D3: Pass | E3: 1 | F3: 33.375 | G3: 640 | H3: 645 | I3: 0 | J3: 20 | K3: =IF($F3="","",$F3*$H3) -> 21526.875 | L3: =IFERROR(ROUND($F3*$G3,-1),"") -> 21360 | N3: =IF($F3="","",IF(N($I3)>0,$F3,0)) -> 0 | O3: =IF($F3="","",N($N3)*N($I3)) -> 0 | P3: =IF(OR($C3=P$1,$C3="Titan Rocks"),$K3,"") | Q3: =IF($C3=Q$1,$K3,"") | R3: =IF($C3=Q$1,$F3,"") | S3: =IF($C3=S$1,$K3,"") | T3: =IF($C3=S$1,$F3,"") | U3: =IF($C3=U$1,$K3,"") | V3: =IF($C3=U$1,$F3,"") | W3: =IF($C3=W$1,$K3,"") | X3: =IF($C3=W$1,$F3,"") | Y3: =IF($C3=Y$1,$K3,"") | Z3: =IF($C3=Y$1,$F3,"") | AA3: =IF($C3=AA$1,$K3,"") | AB3: =IF($C3=AA$1,$F3,"") | AC3: =IF($C3=AC$1,$K3,"") | AD3: =IF($C3=AC$1,$F3,"") | AE3: =IF($C3=AE$1,$K3,"") | AF3: =IF($C3=AE$1,$F3,"") | AG3: =IF($C3=AG$1,$K3,"") | AH3: =IF($C3=AG$1,$F3,"") | AI3: =IF($C3=AI$1,$K3,"") | AJ3: =IF($C3=AI$1,$F3,"") | AK3: =IF($C3=AK$1,$K3,"") | AL3: =IF($C3=AK$1,$F3,"") | AM3: =IF($C3=AM$1,$K3,"") | AN3: =IF($C3=AM$1,$F3,"") | AO3: =IF($C3=AO$1,$K3,"") -> 21526.875 | AP3: =IF($C3=AO$1,$F3,"") -> 33.375 | AQ3: =IF($F3="",0,IF($D3=AQ$1,$F3,0)) -> 33.375 | AR3: =IF($D3=AQ$1,N($K3)-N($L3)-N($O3),0) -> 166.875 | AS3: =IF($F3="",0,IF($D3=AS$1,$F3,0)) -> 0 | AT3: =IF($D3=AS$1,N($K3)-N($L3)-N($O3),0) -> 0 | AU3: =IF(N($J3)>0,N($F3),0) -> 33.375 | AV3: =IF(N($J3)>0,$F3*$J3,0) -> 667.5
A4: 45975 | B4: Rock | C4: Kochammini | D4: WO Pass | E4: =E3+1 -> 2 | F4: 29.02 | G4: 610 | H4: 645 | I4: 0 | J4: 20 | K4: =IF($F4="","",$F4*$H4) -> 18717.9 | L4: =IFERROR(ROUND($F4*$G4,-1),"") -> 17700 | N4: =IF($F4="","",IF(N($I4)>0,$F4,0)) -> 0 | O4: =IF($F4="","",N($N4)*N($I4)) -> 0 | P4: =IF(OR($C4=P$1,$C4="Titan Rocks"),$K4,"") | Q4: =IF($C4=Q$1,$K4,"") | R4: =IF($C4=Q$1,$F4,"") | S4: =IF($C4=S$1,$K4,"") | T4: =IF($C4=S$1,$F4,"") | U4: =IF($C4=U$1,$K4,"") | V4: =IF($C4=U$1,$F4,"") | W4: =IF($C4=W$1,$K4,"") | X4: =IF($C4=W$1,$F4,"") | Y4: =IF($C4=Y$1,$K4,"") | Z4: =IF($C4=Y$1,$F4,"") | AA4: =IF($C4=AA$1,$K4,"") | AB4: =IF($C4=AA$1,$F4,"") | AC4: =IF($C4=AC$1,$K4,"") | AD4: =IF($C4=AC$1,$F4,"") | AE4: =IF($C4=AE$1,$K4,"") | AF4: =IF($C4=AE$1,$F4,"") | AG4: =IF($C4=AG$1,$K4,"") | AH4: =IF($C4=AG$1,$F4,"") | AI4: =IF($C4=AI$1,$K4,"") | AJ4: =IF($C4=AI$1,$F4,"") | AK4: =IF($C4=AK$1,$K4,"") | AL4: =IF($C4=AK$1,$F4,"") | AM4: =IF($C4=AM$1,$K4,"") | AN4: =IF($C4=AM$1,$F4,"") | AO4: =IF($C4=AO$1,$K4,"") -> 18717.9 | AP4: =IF($C4=AO$1,$F4,"") -> 29.02 | AQ4: =IF($F4="",0,IF($D4=AQ$1,$F4,0)) -> 0 | AR4: =IF($D4=AQ$1,N($K4)-N($L4)-N($O4),0) -> 0 | AS4: =IF($F4="",0,IF($D4=AS$1,$F4,0)) -> 29.02 | AT4: =IF($D4=AS$1,N($K4)-N($L4)-N($O4),0) -> 1017.9 | AU4: =IF(N($J4)>0,N($F4),0) -> 29.02 | AV4: =IF(N($J4)>0,$F4*$J4,0) -> 580.4
A5: 45975 | B5: Rock | C5: Kochammini | D5: WO Pass | E5: =E4+1 -> 3 | F5: 30.62 | G5: 610 | H5: 645 | I5: 0 | J5: 20 | K5: =IF($F5="","",$F5*$H5) -> 19749.9 | L5: =IFERROR(ROUND($F5*$G5,-1),"") -> 18680 | N5: =IF($F5="","",IF(N($I5)>0,$F5,0)) -> 0 | O5: =IF($F5="","",N($N5)*N($I5)) -> 0 | P5: =IF(OR($C5=P$1,$C5="Titan Rocks"),$K5,"") | Q5: =IF($C5=Q$1,$K5,"") | R5: =IF($C5=Q$1,$F5,"") | S5: =IF($C5=S$1,$K5,"") | T5: =IF($C5=S$1,$F5,"") | U5: =IF($C5=U$1,$K5,"") | V5: =IF($C5=U$1,$F5,"") | W5: =IF($C5=W$1,$K5,"") | X5: =IF($C5=W$1,$F5,"") | Y5: =IF($C5=Y$1,$K5,"") | Z5: =IF($C5=Y$1,$F5,"") | AA5: =IF($C5=AA$1,$K5,"") | AB5: =IF($C5=AA$1,$F5,"") | AC5: =IF($C5=AC$1,$K5,"") | AD5: =IF($C5=AC$1,$F5,"") | AE5: =IF($C5=AE$1,$K5,"") | AF5: =IF($C5=AE$1,$F5,"") | AG5: =IF($C5=AG$1,$K5,"") | AH5: =IF($C5=AG$1,$F5,"") | AI5: =IF($C5=AI$1,$K5,"") | AJ5: =IF($C5=AI$1,$F5,"") | AK5: =IF($C5=AK$1,$K5,"") | AL5: =IF($C5=AK$1,$F5,"") | AM5: =IF($C5=AM$1,$K5,"") | AN5: =IF($C5=AM$1,$F5,"") | AO5: =IF($C5=AO$1,$K5,"") -> 19749.9 | AP5: =IF($C5=AO$1,$F5,"") -> 30.62 | AQ5: =IF($F5="",0,IF($D5=AQ$1,$F5,0)) -> 0 | AR5: =IF($D5=AQ$1,N($K5)-N($L5)-N($O5),0) -> 0 | AS5: =IF($F5="",0,IF($D5=AS$1,$F5,0)) -> 30.62 | AT5: =IF($D5=AS$1,N($K5)-N($L5)-N($O5),0) -> 1069.9 | AU5: =IF(N($J5)>0,N($F5),0) -> 30.62 | AV5: =IF(N($J5)>0,$F5*$J5,0) -> 612.4
A6: 45978 | B6: Rock | C6: Kochammini | D6: Pass | E6: =E5+1 -> 4 | F6: 29.44 | G6: 640 | H6: 645 | I6: 0 | J6: 20 | K6: =IF($F6="","",$F6*$H6) -> 18988.8 | L6: =IFERROR(ROUND($F6*$G6,-1),"") -> 18840 | N6: =IF($F6="","",IF(N($I6)>0,$F6,0)) -> 0 | O6: =IF($F6="","",N($N6)*N($I6)) -> 0 | P6: =IF(OR($C6=P$1,$C6="Titan Rocks"),$K6,"") | Q6: =IF($C6=Q$1,$K6,"") | R6: =IF($C6=Q$1,$F6,"") | S6: =IF($C6=S$1,$K6,"") | T6: =IF($C6=S$1,$F6,"") | U6: =IF($C6=U$1,$K6,"") | V6: =IF($C6=U$1,$F6,"") | W6: =IF($C6=W$1,$K6,"") | X6: =IF($C6=W$1,$F6,"") | Y6: =IF($C6=Y$1,$K6,"") | Z6: =IF($C6=Y$1,$F6,"") | AA6: =IF($C6=AA$1,$K6,"") | AB6: =IF($C6=AA$1,$F6,"") | AC6: =IF($C6=AC$1,$K6,"") | AD6: =IF($C6=AC$1,$F6,"") | AE6: =IF($C6=AE$1,$K6,"") | AF6: =IF($C6=AE$1,$F6,"") | AG6: =IF($C6=AG$1,$K6,"") | AH6: =IF($C6=AG$1,$F6,"") | AI6: =IF($C6=AI$1,$K6,"") | AJ6: =IF($C6=AI$1,$F6,"") | AK6: =IF($C6=AK$1,$K6,"") | AL6: =IF($C6=AK$1,$F6,"") | AM6: =IF($C6=AM$1,$K6,"") | AN6: =IF($C6=AM$1,$F6,"") | AO6: =IF($C6=AO$1,$K6,"") -> 18988.8 | AP6: =IF($C6=AO$1,$F6,"") -> 29.44 | AQ6: =IF($F6="",0,IF($D6=AQ$1,$F6,0)) -> 29.44 | AR6: =IF($D6=AQ$1,N($K6)-N($L6)-N($O6),0) -> 148.8 | AS6: =IF($F6="",0,IF($D6=AS$1,$F6,0)) -> 0 | AT6: =IF($D6=AS$1,N($K6)-N($L6)-N($O6),0) -> 0 | AU6: =IF(N($J6)>0,N($F6),0) -> 29.44 | AV6: =IF(N($J6)>0,$F6*$J6,0) -> 588.8
A7: 45978 | B7: Rock | C7: Kochammini | D7: Pass | E7: =E6+1 -> 5 | F7: 31.16 | G7: 640 | H7: 645 | I7: 0 | J7: 20 | K7: =IF($F7="","",$F7*$H7) -> 20098.2 | L7: =IFERROR(ROUND($F7*$G7,-1),"") -> 19940 | N7: =IF($F7="","",IF(N($I7)>0,$F7,0)) -> 0 | O7: =IF($F7="","",N($N7)*N($I7)) -> 0 | P7: =IF(OR($C7=P$1,$C7="Titan Rocks"),$K7,"") | Q7: =IF($C7=Q$1,$K7,"") | R7: =IF($C7=Q$1,$F7,"") | S7: =IF($C7=S$1,$K7,"") | T7: =IF($C7=S$1,$F7,"") | U7: =IF($C7=U$1,$K7,"") | V7: =IF($C7=U$1,$F7,"") | W7: =IF($C7=W$1,$K7,"") | X7: =IF($C7=W$1,$F7,"") | Y7: =IF($C7=Y$1,$K7,"") | Z7: =IF($C7=Y$1,$F7,"") | AA7: =IF($C7=AA$1,$K7,"") | AB7: =IF($C7=AA$1,$F7,"") | AC7: =IF($C7=AC$1,$K7,"") | AD7: =IF($C7=AC$1,$F7,"") | AE7: =IF($C7=AE$1,$K7,"") | AF7: =IF($C7=AE$1,$F7,"") | AG7: =IF($C7=AG$1,$K7,"") | AH7: =IF($C7=AG$1,$F7,"") | AI7: =IF($C7=AI$1,$K7,"") | AJ7: =IF($C7=AI$1,$F7,"") | AK7: =IF($C7=AK$1,$K7,"") | AL7: =IF($C7=AK$1,$F7,"") | AM7: =IF($C7=AM$1,$K7,"") | AN7: =IF($C7=AM$1,$F7,"") | AO7: =IF($C7=AO$1,$K7,"") -> 20098.2 | AP7: =IF($C7=AO$1,$F7,"") -> 31.16 | AQ7: =IF($F7="",0,IF($D7=AQ$1,$F7,0)) -> 31.16 | AR7: =IF($D7=AQ$1,N($K7)-N($L7)-N($O7),0) -> 158.2 | AS7: =IF($F7="",0,IF($D7=AS$1,$F7,0)) -> 0 | AT7: =IF($D7=AS$1,N($K7)-N($L7)-N($O7),0) -> 0 | AU7: =IF(N($J7)>0,N($F7),0) -> 31.16 | AV7: =IF(N($J7)>0,$F7*$J7,0) -> 623.2
A8: 45978 | B8: Rock | C8: Kochammini | D8: WO Pass | E8: =E7+1 -> 6 | F8: 28.58 | G8: 610 | H8: 645 | I8: 0 | J8: 20 | K8: =IF($F8="","",$F8*$H8) -> 18434.1 | L8: =IFERROR(ROUND($F8*$G8,-1),"") -> 17430 | N8: =IF($F8="","",IF(N($I8)>0,$F8,0)) -> 0 | O8: =IF($F8="","",N($N8)*N($I8)) -> 0 | P8: =IF(OR($C8=P$1,$C8="Titan Rocks"),$K8,"") | Q8: =IF($C8=Q$1,$K8,"") | R8: =IF($C8=Q$1,$F8,"") | S8: =IF($C8=S$1,$K8,"") | T8: =IF($C8=S$1,$F8,"") | U8: =IF($C8=U$1,$K8,"") | V8: =IF($C8=U$1,$F8,"") | W8: =IF($C8=W$1,$K8,"") | X8: =IF($C8=W$1,$F8,"") | Y8: =IF($C8=Y$1,$K8,"") | Z8: =IF($C8=Y$1,$F8,"") | AA8: =IF($C8=AA$1,$K8,"") | AB8: =IF($C8=AA$1,$F8,"") | AC8: =IF($C8=AC$1,$K8,"") | AD8: =IF($C8=AC$1,$F8,"") | AE8: =IF($C8=AE$1,$K8,"") | AF8: =IF($C8=AE$1,$F8,"") | AG8: =IF($C8=AG$1,$K8,"") | AH8: =IF($C8=AG$1,$F8,"") | AI8: =IF($C8=AI$1,$K8,"") | AJ8: =IF($C8=AI$1,$F8,"") | AK8: =IF($C8=AK$1,$K8,"") | AL8: =IF($C8=AK$1,$F8,"") | AM8: =IF($C8=AM$1,$K8,"") | AN8: =IF($C8=AM$1,$F8,"") | AO8: =IF($C8=AO$1,$K8,"") -> 18434.1 | AP8: =IF($C8=AO$1,$F8,"") -> 28.58 | AQ8: =IF($F8="",0,IF($D8=AQ$1,$F8,0)) -> 0 | AR8: =IF($D8=AQ$1,N($K8)-N($L8)-N($O8),0) -> 0 | AS8: =IF($F8="",0,IF($D8=AS$1,$F8,0)) -> 28.58 | AT8: =IF($D8=AS$1,N($K8)-N($L8)-N($O8),0) -> 1004.1 | AU8: =IF(N($J8)>0,N($F8),0) -> 28.58 | AV8: =IF(N($J8)>0,$F8*$J8,0) -> 571.6
A9: 45978 | B9: Rock | C9: Kochammini | D9: WO Pass | E9: =E8+1 -> 7 | F9: 31.08 | G9: 610 | H9: 645 | I9: 0 | J9: 20 | K9: =IF($F9="","",$F9*$H9) -> 20046.6 | L9: =IFERROR(ROUND($F9*$G9,-1),"") -> 18960 | N9: =IF($F9="","",IF(N($I9)>0,$F9,0)) -> 0 | O9: =IF($F9="","",N($N9)*N($I9)) -> 0 | P9: =IF(OR($C9=P$1,$C9="Titan Rocks"),$K9,"") | Q9: =IF($C9=Q$1,$K9,"") | R9: =IF($C9=Q$1,$F9,"") | S9: =IF($C9=S$1,$K9,"") | T9: =IF($C9=S$1,$F9,"") | U9: =IF($C9=U$1,$K9,"") | V9: =IF($C9=U$1,$F9,"") | W9: =IF($C9=W$1,$K9,"") | X9: =IF($C9=W$1,$F9,"") | Y9: =IF($C9=Y$1,$K9,"") | Z9: =IF($C9=Y$1,$F9,"") | AA9: =IF($C9=AA$1,$K9,"") | AB9: =IF($C9=AA$1,$F9,"") | AC9: =IF($C9=AC$1,$K9,"") | AD9: =IF($C9=AC$1,$F9,"") | AE9: =IF($C9=AE$1,$K9,"") | AF9: =IF($C9=AE$1,$F9,"") | AG9: =IF($C9=AG$1,$K9,"") | AH9: =IF($C9=AG$1,$F9,"") | AI9: =IF($C9=AI$1,$K9,"") | AJ9: =IF($C9=AI$1,$F9,"") | AK9: =IF($C9=AK$1,$K9,"") | AL9: =IF($C9=AK$1,$F9,"") | AM9: =IF($C9=AM$1,$K9,"") | AN9: =IF($C9=AM$1,$F9,"") | AO9: =IF($C9=AO$1,$K9,"") -> 20046.6 | AP9: =IF($C9=AO$1,$F9,"") -> 31.08 | AQ9: =IF($F9="",0,IF($D9=AQ$1,$F9,0)) -> 0 | AR9: =IF($D9=AQ$1,N($K9)-N($L9)-N($O9),0) -> 0 | AS9: =IF($F9="",0,IF($D9=AS$1,$F9,0)) -> 31.08 | AT9: =IF($D9=AS$1,N($K9)-N($L9)-N($O9),0) -> 1086.6 | AU9: =IF(N($J9)>0,N($F9),0) -> 31.08 | AV9: =IF(N($J9)>0,$F9*$J9,0) -> 621.6
A10: 45978 | B10: Rock | C10: Kochammini | D10: WO Pass | E10: =E9+1 -> 8 | F10: 32.95 | G10: 610 | H10: 645 | I10: 0 | J10: 20 | K10: =IF($F10="","",$F10*$H10) -> 21252.75 | L10: =IFERROR(ROUND($F10*$G10,-1),"") -> 20100 | N10: =IF($F10="","",IF(N($I10)>0,$F10,0)) -> 0 | O10: =IF($F10="","",N($N10)*N($I10)) -> 0 | P10: =IF(OR($C10=P$1,$C10="Titan Rocks"),$K10,"") | Q10: =IF($C10=Q$1,$K10,"") | R10: =IF($C10=Q$1,$F10,"") | S10: =IF($C10=S$1,$K10,"") | T10: =IF($C10=S$1,$F10,"") | U10: =IF($C10=U$1,$K10,"") | V10: =IF($C10=U$1,$F10,"") | W10: =IF($C10=W$1,$K10,"") | X10: =IF($C10=W$1,$F10,"") | Y10: =IF($C10=Y$1,$K10,"") | Z10: =IF($C10=Y$1,$F10,"") | AA10: =IF($C10=AA$1,$K10,"") | AB10: =IF($C10=AA$1,$F10,"") | AC10: =IF($C10=AC$1,$K10,"") | AD10: =IF($C10=AC$1,$F10,"") | AE10: =IF($C10=AE$1,$K10,"") | AF10: =IF($C10=AE$1,$F10,"") | AG10: =IF($C10=AG$1,$K10,"") | AH10: =IF($C10=AG$1,$F10,"") | AI10: =IF($C10=AI$1,$K10,"") | AJ10: =IF($C10=AI$1,$F10,"") | AK10: =IF($C10=AK$1,$K10,"") | AL10: =IF($C10=AK$1,$F10,"") | AM10: =IF($C10=AM$1,$K10,"") | AN10: =IF($C10=AM$1,$F10,"") | AO10: =IF($C10=AO$1,$K10,"") -> 21252.75 | AP10: =IF($C10=AO$1,$F10,"") -> 32.95 | AQ10: =IF($F10="",0,IF($D10=AQ$1,$F10,0)) -> 0 | AR10: =IF($D10=AQ$1,N($K10)-N($L10)-N($O10),0) -> 0 | AS10: =IF($F10="",0,IF($D10=AS$1,$F10,0)) -> 32.95 | AT10: =IF($D10=AS$1,N($K10)-N($L10)-N($O10),0) -> 1152.75 | AU10: =IF(N($J10)>0,N($F10),0) -> 32.95 | AV10: =IF(N($J10)>0,$F10*$J10,0) -> 659
A11: 45978 | B11: Rock | C11: Kochammini | D11: WO Pass | E11: =E10+1 -> 9 | F11: 32.39 | G11: 610 | H11: 645 | I11: 0 | J11: 20 | K11: =IF($F11="","",$F11*$H11) -> 20891.55 | L11: =IFERROR(ROUND($F11*$G11,-1),"") -> 19760 | N11: =IF($F11="","",IF(N($I11)>0,$F11,0)) -> 0 | O11: =IF($F11="","",N($N11)*N($I11)) -> 0 | P11: =IF(OR($C11=P$1,$C11="Titan Rocks"),$K11,"") | Q11: =IF($C11=Q$1,$K11,"") | R11: =IF($C11=Q$1,$F11,"") | S11: =IF($C11=S$1,$K11,"") | T11: =IF($C11=S$1,$F11,"") | U11: =IF($C11=U$1,$K11,"") | V11: =IF($C11=U$1,$F11,"") | W11: =IF($C11=W$1,$K11,"") | X11: =IF($C11=W$1,$F11,"") | Y11: =IF($C11=Y$1,$K11,"") | Z11: =IF($C11=Y$1,$F11,"") | AA11: =IF($C11=AA$1,$K11,"") | AB11: =IF($C11=AA$1,$F11,"") | AC11: =IF($C11=AC$1,$K11,"") | AD11: =IF($C11=AC$1,$F11,"") | AE11: =IF($C11=AE$1,$K11,"") | AF11: =IF($C11=AE$1,$F11,"") | AG11: =IF($C11=AG$1,$K11,"") | AH11: =IF($C11=AG$1,$F11,"") | AI11: =IF($C11=AI$1,$K11,"") | AJ11: =IF($C11=AI$1,$F11,"") | AK11: =IF($C11=AK$1,$K11,"") | AL11: =IF($C11=AK$1,$F11,"") | AM11: =IF($C11=AM$1,$K11,"") | AN11: =IF($C11=AM$1,$F11,"") | AO11: =IF($C11=AO$1,$K11,"") -> 20891.55 | AP11: =IF($C11=AO$1,$F11,"") -> 32.39 | AQ11: =IF($F11="",0,IF($D11=AQ$1,$F11,0)) -> 0 | AR11: =IF($D11=AQ$1,N($K11)-N($L11)-N($O11),0) -> 0 | AS11: =IF($F11="",0,IF($D11=AS$1,$F11,0)) -> 32.39 | AT11: =IF($D11=AS$1,N($K11)-N($L11)-N($O11),0) -> 1131.55 | AU11: =IF(N($J11)>0,N($F11),0) -> 32.39 | AV11: =IF(N($J11)>0,$F11*$J11,0) -> 647.8
A12: 45978 | B12: Rock | C12: Kochammini | D12: WO Pass | E12: =E11+1 -> 10 | F12: 33.2 | G12: 610 | H12: 645 | I12: 0 | J12: 20 | K12: =IF($F12="","",$F12*$H12) -> 21414 | L12: =IFERROR(ROUND($F12*$G12,-1),"") -> 20250 | N12: =IF($F12="","",IF(N($I12)>0,$F12,0)) -> 0 | O12: =IF($F12="","",N($N12)*N($I12)) -> 0 | P12: =IF(OR($C12=P$1,$C12="Titan Rocks"),$K12,"") | Q12: =IF($C12=Q$1,$K12,"") | R12: =IF($C12=Q$1,$F12,"") | S12: =IF($C12=S$1,$K12,"") | T12: =IF($C12=S$1,$F12,"") | U12: =IF($C12=U$1,$K12,"") | V12: =IF($C12=U$1,$F12,"") | W12: =IF($C12=W$1,$K12,"") | X12: =IF($C12=W$1,$F12,"") | Y12: =IF($C12=Y$1,$K12,"") | Z12: =IF($C12=Y$1,$F12,"") | AA12: =IF($C12=AA$1,$K12,"") | AB12: =IF($C12=AA$1,$F12,"") | AC12: =IF($C12=AC$1,$K12,"") | AD12: =IF($C12=AC$1,$F12,"") | AE12: =IF($C12=AE$1,$K12,"") | AF12: =IF($C12=AE$1,$F12,"") | AG12: =IF($C12=AG$1,$K12,"") | AH12: =IF($C12=AG$1,$F12,"") | AI12: =IF($C12=AI$1,$K12,"") | AJ12: =IF($C12=AI$1,$F12,"") | AK12: =IF($C12=AK$1,$K12,"") | AL12: =IF($C12=AK$1,$F12,"") | AM12: =IF($C12=AM$1,$K12,"") | AN12: =IF($C12=AM$1,$F12,"") | AO12: =IF($C12=AO$1,$K12,"") -> 21414 | AP12: =IF($C12=AO$1,$F12,"") -> 33.2 | AQ12: =IF($F12="",0,IF($D12=AQ$1,$F12,0)) -> 0 | AR12: =IF($D12=AQ$1,N($K12)-N($L12)-N($O12),0) -> 0 | AS12: =IF($F12="",0,IF($D12=AS$1,$F12,0)) -> 33.2 | AT12: =IF($D12=AS$1,N($K12)-N($L12)-N($O12),0) -> 1164 | AU12: =IF(N($J12)>0,N($F12),0) -> 33.2 | AV12: =IF(N($J12)>0,$F12*$J12,0) -> 664
A13: 45978 | B13: Rock | C13: Kochammini | D13: WO Pass | E13: =E12+1 -> 11 | F13: 31.53 | G13: 610 | H13: 645 | I13: 0 | J13: 20 | K13: =IF($F13="","",$F13*$H13) -> 20336.85 | L13: =IFERROR(ROUND($F13*$G13,-1),"") -> 19230 | N13: =IF($F13="","",IF(N($I13)>0,$F13,0)) -> 0 | O13: =IF($F13="","",N($N13)*N($I13)) -> 0 | P13: =IF(OR($C13=P$1,$C13="Titan Rocks"),$K13,"") | Q13: =IF($C13=Q$1,$K13,"") | R13: =IF($C13=Q$1,$F13,"") | S13: =IF($C13=S$1,$K13,"") | T13: =IF($C13=S$1,$F13,"") | U13: =IF($C13=U$1,$K13,"") | V13: =IF($C13=U$1,$F13,"") | W13: =IF($C13=W$1,$K13,"") | X13: =IF($C13=W$1,$F13,"") | Y13: =IF($C13=Y$1,$K13,"") | Z13: =IF($C13=Y$1,$F13,"") | AA13: =IF($C13=AA$1,$K13,"") | AB13: =IF($C13=AA$1,$F13,"") | AC13: =IF($C13=AC$1,$K13,"") | AD13: =IF($C13=AC$1,$F13,"") | AE13: =IF($C13=AE$1,$K13,"") | AF13: =IF($C13=AE$1,$F13,"") | AG13: =IF($C13=AG$1,$K13,"") | AH13: =IF($C13=AG$1,$F13,"") | AI13: =IF($C13=AI$1,$K13,"") | AJ13: =IF($C13=AI$1,$F13,"") | AK13: =IF($C13=AK$1,$K13,"") | AL13: =IF($C13=AK$1,$F13,"") | AM13: =IF($C13=AM$1,$K13,"") | AN13: =IF($C13=AM$1,$F13,"") | AO13: =IF($C13=AO$1,$K13,"") -> 20336.85 | AP13: =IF($C13=AO$1,$F13,"") -> 31.53 | AQ13: =IF($F13="",0,IF($D13=AQ$1,$F13,0)) -> 0 | AR13: =IF($D13=AQ$1,N($K13)-N($L13)-N($O13),0) -> 0 | AS13: =IF($F13="",0,IF($D13=AS$1,$F13,0)) -> 31.53 | AT13: =IF($D13=AS$1,N($K13)-N($L13)-N($O13),0) -> 1106.85 | AU13: =IF(N($J13)>0,N($F13),0) -> 31.53 | AV13: =IF(N($J13)>0,$F13*$J13,0) -> 630.6
A14: 45978 | B14: Rock | C14: Kochammini | D14: WO Pass | E14: =E13+1 -> 12 | F14: 31.62 | G14: 610 | H14: 645 | I14: 0 | J14: 20 | K14: =IF($F14="","",$F14*$H14) -> 20394.9 | L14: =IFERROR(ROUND($F14*$G14,-1),"") -> 19290 | N14: =IF($F14="","",IF(N($I14)>0,$F14,0)) -> 0 | O14: =IF($F14="","",N($N14)*N($I14)) -> 0 | P14: =IF(OR($C14=P$1,$C14="Titan Rocks"),$K14,"") | Q14: =IF($C14=Q$1,$K14,"") | R14: =IF($C14=Q$1,$F14,"") | S14: =IF($C14=S$1,$K14,"") | T14: =IF($C14=S$1,$F14,"") | U14: =IF($C14=U$1,$K14,"") | V14: =IF($C14=U$1,$F14,"") | W14: =IF($C14=W$1,$K14,"") | X14: =IF($C14=W$1,$F14,"") | Y14: =IF($C14=Y$1,$K14,"") | Z14: =IF($C14=Y$1,$F14,"") | AA14: =IF($C14=AA$1,$K14,"") | AB14: =IF($C14=AA$1,$F14,"") | AC14: =IF($C14=AC$1,$K14,"") | AD14: =IF($C14=AC$1,$F14,"") | AE14: =IF($C14=AE$1,$K14,"") | AF14: =IF($C14=AE$1,$F14,"") | AG14: =IF($C14=AG$1,$K14,"") | AH14: =IF($C14=AG$1,$F14,"") | AI14: =IF($C14=AI$1,$K14,"") | AJ14: =IF($C14=AI$1,$F14,"") | AK14: =IF($C14=AK$1,$K14,"") | AL14: =IF($C14=AK$1,$F14,"") | AM14: =IF($C14=AM$1,$K14,"") | AN14: =IF($C14=AM$1,$F14,"") | AO14: =IF($C14=AO$1,$K14,"") -> 20394.9 | AP14: =IF($C14=AO$1,$F14,"") -> 31.62 | AQ14: =IF($F14="",0,IF($D14=AQ$1,$F14,0)) -> 0 | AR14: =IF($D14=AQ$1,N($K14)-N($L14)-N($O14),0) -> 0 | AS14: =IF($F14="",0,IF($D14=AS$1,$F14,0)) -> 31.62 | AT14: =IF($D14=AS$1,N($K14)-N($L14)-N($O14),0) -> 1104.9 | AU14: =IF(N($J14)>0,N($F14),0) -> 31.62 | AV14: =IF(N($J14)>0,$F14*$J14,0) -> 632.4
A15: 45978 | B15: Rock | C15: Kochammini | D15: WO Pass | E15: =E14+1 -> 13 | F15: 32.09 | G15: 610 | H15: 645 | I15: 0 | J15: 20 | K15: =IF($F15="","",$F15*$H15) -> 20698.05 | L15: =IFERROR(ROUND($F15*$G15,-1),"") -> 19570 | N15: =IF($F15="","",IF(N($I15)>0,$F15,0)) -> 0 | O15: =IF($F15="","",N($N15)*N($I15)) -> 0 | P15: =IF(OR($C15=P$1,$C15="Titan Rocks"),$K15,"") | Q15: =IF($C15=Q$1,$K15,"") | R15: =IF($C15=Q$1,$F15,"") | S15: =IF($C15=S$1,$K15,"") | T15: =IF($C15=S$1,$F15,"") | U15: =IF($C15=U$1,$K15,"") | V15: =IF($C15=U$1,$F15,"") | W15: =IF($C15=W$1,$K15,"") | X15: =IF($C15=W$1,$F15,"") | Y15: =IF($C15=Y$1,$K15,"") | Z15: =IF($C15=Y$1,$F15,"") | AA15: =IF($C15=AA$1,$K15,"") | AB15: =IF($C15=AA$1,$F15,"") | AC15: =IF($C15=AC$1,$K15,"") | AD15: =IF($C15=AC$1,$F15,"") | AE15: =IF($C15=AE$1,$K15,"") | AF15: =IF($C15=AE$1,$F15,"") | AG15: =IF($C15=AG$1,$K15,"") | AH15: =IF($C15=AG$1,$F15,"") | AI15: =IF($C15=AI$1,$K15,"") | AJ15: =IF($C15=AI$1,$F15,"") | AK15: =IF($C15=AK$1,$K15,"") | AL15: =IF($C15=AK$1,$F15,"") | AM15: =IF($C15=AM$1,$K15,"") | AN15: =IF($C15=AM$1,$F15,"") | AO15: =IF($C15=AO$1,$K15,"") -> 20698.05 | AP15: =IF($C15=AO$1,$F15,"") -> 32.09 | AQ15: =IF($F15="",0,IF($D15=AQ$1,$F15,0)) -> 0 | AR15: =IF($D15=AQ$1,N($K15)-N($L15)-N($O15),0) -> 0 | AS15: =IF($F15="",0,IF($D15=AS$1,$F15,0)) -> 32.09 | AT15: =IF($D15=AS$1,N($K15)-N($L15)-N($O15),0) -> 1128.05 | AU15: =IF(N($J15)>0,N($F15),0) -> 32.09 | AV15: =IF(N($J15)>0,$F15*$J15,0) -> 641.8
... A51: 45988 | B51: Rock | C51: Kochammini | D51: Pass | E51: =E50+1 -> 49 | F51: 30.24 | G51: 640 | H51: 645 | I51: 0 | J51: 20 | K51: =IF($F51="","",$F51*$H51) -> 19504.8 | L51: =IFERROR(ROUND($F51*$G51,-1),"") -> 19350 | N51: =IF($F51="","",IF(N($I51)>0,$F51,0)) -> 0 | O51: =IF($F51="","",N($N51)*N($I51)) -> 0 | P51: =IF(OR($C51=P$1,$C51="Titan Rocks"),$K51,"") | Q51: =IF($C51=Q$1,$K51,"") | R51: =IF($C51=Q$1,$F51,"") | S51: =IF($C51=S$1,$K51,"") | T51: =IF($C51=S$1,$F51,"") | U51: =IF($C51=U$1,$K51,"") | V51: =IF($C51=U$1,$F51,"") | W51: =IF($C51=W$1,$K51,"") | X51: =IF($C51=W$1,$F51,"") | Y51: =IF($C51=Y$1,$K51,"") | Z51: =IF($C51=Y$1,$F51,"") | AA51: =IF($C51=AA$1,$K51,"") | AB51: =IF($C51=AA$1,$F51,"") | AC51: =IF($C51=AC$1,$K51,"") | AD51: =IF($C51=AC$1,$F51,"") | AE51: =IF($C51=AE$1,$K51,"") | AF51: =IF($C51=AE$1,$F51,"") | AG51: =IF($C51=AG$1,$K51,"") | AH51: =IF($C51=AG$1,$F51,"") | AI51: =IF($C51=AI$1,$K51,"") | AJ51: =IF($C51=AI$1,$F51,"") | AK51: =IF($C51=AK$1,$K51,"") | AL51: =IF($C51=AK$1,$F51,"") | AM51: =IF($C51=AM$1,$K51,"") | AN51: =IF($C51=AM$1,$F51,"") | AO51: =IF($C51=AO$1,$K51,"") -> 19504.8 | AP51: =IF($C51=AO$1,$F51,"") -> 30.24 | AQ51: =IF($F51="",0,IF($D51=AQ$1,$F51,0)) -> 30.24 | AR51: =IF($D51=AQ$1,N($K51)-N($L51)-N($O51),0) -> 154.8 | AS51: =IF($F51="",0,IF($D51=AS$1,$F51,0)) -> 0 | AT51: =IF($D51=AS$1,N($K51)-N($L51)-N($O51),0) -> 0 | AU51: =IF(N($J51)>0,N($F51),0) -> 30.24 | AV51: =IF(N($J51)>0,$F51*$J51,0) -> 604.8
A52: 45990 | B52: Rock | C52: MR Granites | D52: WO Pass | E52: =E51+1 -> 50 | F52: 31.36 | G52: 610 | H52: 875 | I52: 220 | J52: 20 | K52: =IF($F52="","",$F52*$H52) -> 27440 | L52: =IFERROR(ROUND($F52*$G52,-1),"") -> 19130 | M52: KL 05 AS 7477 | N52: =IF($F52="","",IF(N($I52)>0,$F52,0)) -> 31.36 | O52: =IF($F52="","",N($N52)*N($I52)) -> 6899.2 | P52: =IF(OR($C52=P$1,$C52="Titan Rocks"),$K52,"") | Q52: =IF($C52=Q$1,$K52,"") -> 27440 | R52: =IF($C52=Q$1,$F52,"") -> 31.36 | S52: =IF($C52=S$1,$K52,"") | T52: =IF($C52=S$1,$F52,"") | U52: =IF($C52=U$1,$K52,"") | V52: =IF($C52=U$1,$F52,"") | W52: =IF($C52=W$1,$K52,"") | X52: =IF($C52=W$1,$F52,"") | Y52: =IF($C52=Y$1,$K52,"") | Z52: =IF($C52=Y$1,$F52,"") | AA52: =IF($C52=AA$1,$K52,"") | AB52: =IF($C52=AA$1,$F52,"") | AC52: =IF($C52=AC$1,$K52,"") | AD52: =IF($C52=AC$1,$F52,"") | AE52: =IF($C52=AE$1,$K52,"") | AF52: =IF($C52=AE$1,$F52,"") | AG52: =IF($C52=AG$1,$K52,"") | AH52: =IF($C52=AG$1,$F52,"") | AI52: =IF($C52=AI$1,$K52,"") | AJ52: =IF($C52=AI$1,$F52,"") | AK52: =IF($C52=AK$1,$K52,"") | AL52: =IF($C52=AK$1,$F52,"") | AM52: =IF($C52=AM$1,$K52,"") | AN52: =IF($C52=AM$1,$F52,"") | AO52: =IF($C52=AO$1,$K52,"") | AP52: =IF($C52=AO$1,$F52,"") | AQ52: =IF($F52="",0,IF($D52=AQ$1,$F52,0)) -> 0 | AR52: =IF($D52=AQ$1,N($K52)-N($L52)-N($O52),0) -> 0 | AS52: =IF($F52="",0,IF($D52=AS$1,$F52,0)) -> 31.36 | AT52: =IF($D52=AS$1,N($K52)-N($L52)-N($O52),0) -> 1410.8 | AU52: =IF(N($J52)>0,N($F52),0) -> 31.36 | AV52: =IF(N($J52)>0,$F52*$J52,0) -> 627.2
A53: 45990 | B53: Rock | C53: Kochammini | D53: WO Pass | E53: =E52+1 -> 51 | F53: 27.71 | G53: 610 | H53: 645 | I53: 0 | J53: 20 | K53: =IF($F53="","",$F53*$H53) -> 17872.95 | L53: =IFERROR(ROUND($F53*$G53,-1),"") -> 16900 | N53: =IF($F53="","",IF(N($I53)>0,$F53,0)) -> 0 | O53: =IF($F53="","",N($N53)*N($I53)) -> 0 | P53: =IF(OR($C53=P$1,$C53="Titan Rocks"),$K53,"") | Q53: =IF($C53=Q$1,$K53,"") | R53: =IF($C53=Q$1,$F53,"") | S53: =IF($C53=S$1,$K53,"") | T53: =IF($C53=S$1,$F53,"") | U53: =IF($C53=U$1,$K53,"") | V53: =IF($C53=U$1,$F53,"") | W53: =IF($C53=W$1,$K53,"") | X53: =IF($C53=W$1,$F53,"") | Y53: =IF($C53=Y$1,$K53,"") | Z53: =IF($C53=Y$1,$F53,"") | AA53: =IF($C53=AA$1,$K53,"") | AB53: =IF($C53=AA$1,$F53,"") | AC53: =IF($C53=AC$1,$K53,"") | AD53: =IF($C53=AC$1,$F53,"") | AE53: =IF($C53=AE$1,$K53,"") | AF53: =IF($C53=AE$1,$F53,"") | AG53: =IF($C53=AG$1,$K53,"") | AH53: =IF($C53=AG$1,$F53,"") | AI53: =IF($C53=AI$1,$K53,"") | AJ53: =IF($C53=AI$1,$F53,"") | AK53: =IF($C53=AK$1,$K53,"") | AL53: =IF($C53=AK$1,$F53,"") | AM53: =IF($C53=AM$1,$K53,"") | AN53: =IF($C53=AM$1,$F53,"") | AO53: =IF($C53=AO$1,$K53,"") -> 17872.95 | AP53: =IF($C53=AO$1,$F53,"") -> 27.71 | AQ53: =IF($F53="",0,IF($D53=AQ$1,$F53,0)) -> 0 | AR53: =IF($D53=AQ$1,N($K53)-N($L53)-N($O53),0) -> 0 | AS53: =IF($F53="",0,IF($D53=AS$1,$F53,0)) -> 27.71 | AT53: =IF($D53=AS$1,N($K53)-N($L53)-N($O53),0) -> 972.95 | AU53: =IF(N($J53)>0,N($F53),0) -> 27.71 | AV53: =IF(N($J53)>0,$F53*$J53,0) -> 554.2
A54: 45990 | B54: Rock | C54: Kochammini | D54: WO Pass | E54: =E53+1 -> 52 | F54: 31.75 | G54: 610 | H54: 645 | I54: 0 | J54: 20 | K54: =IF($F54="","",$F54*$H54) -> 20478.75 | L54: =IFERROR(ROUND($F54*$G54,-1),"") -> 19370 | N54: =IF($F54="","",IF(N($I54)>0,$F54,0)) -> 0 | O54: =IF($F54="","",N($N54)*N($I54)) -> 0 | P54: =IF(OR($C54=P$1,$C54="Titan Rocks"),$K54,"") | Q54: =IF($C54=Q$1,$K54,"") | R54: =IF($C54=Q$1,$F54,"") | S54: =IF($C54=S$1,$K54,"") | T54: =IF($C54=S$1,$F54,"") | U54: =IF($C54=U$1,$K54,"") | V54: =IF($C54=U$1,$F54,"") | W54: =IF($C54=W$1,$K54,"") | X54: =IF($C54=W$1,$F54,"") | Y54: =IF($C54=Y$1,$K54,"") | Z54: =IF($C54=Y$1,$F54,"") | AA54: =IF($C54=AA$1,$K54,"") | AB54: =IF($C54=AA$1,$F54,"") | AC54: =IF($C54=AC$1,$K54,"") | AD54: =IF($C54=AC$1,$F54,"") | AE54: =IF($C54=AE$1,$K54,"") | AF54: =IF($C54=AE$1,$F54,"") | AG54: =IF($C54=AG$1,$K54,"") | AH54: =IF($C54=AG$1,$F54,"") | AI54: =IF($C54=AI$1,$K54,"") | AJ54: =IF($C54=AI$1,$F54,"") | AK54: =IF($C54=AK$1,$K54,"") | AL54: =IF($C54=AK$1,$F54,"") | AM54: =IF($C54=AM$1,$K54,"") | AN54: =IF($C54=AM$1,$F54,"") | AO54: =IF($C54=AO$1,$K54,"") -> 20478.75 | AP54: =IF($C54=AO$1,$F54,"") -> 31.75 | AQ54: =IF($F54="",0,IF($D54=AQ$1,$F54,0)) -> 0 | AR54: =IF($D54=AQ$1,N($K54)-N($L54)-N($O54),0) -> 0 | AS54: =IF($F54="",0,IF($D54=AS$1,$F54,0)) -> 31.75 | AT54: =IF($D54=AS$1,N($K54)-N($L54)-N($O54),0) -> 1108.75 | AU54: =IF(N($J54)>0,N($F54),0) -> 31.75 | AV54: =IF(N($J54)>0,$F54*$J54,0) -> 635
A55: 45990 | B55: Rock | C55: Kochammini | D55: WO Pass | E55: =E54+1 -> 53 | F55: 31.66 | G55: 610 | H55: 645 | I55: 0 | J55: 20 | K55: =IF($F55="","",$F55*$H55) -> 20420.7 | L55: =IFERROR(ROUND($F55*$G55,-1),"") -> 19310 | N55: =IF($F55="","",IF(N($I55)>0,$F55,0)) -> 0 | O55: =IF($F55="","",N($N55)*N($I55)) -> 0 | P55: =IF(OR($C55=P$1,$C55="Titan Rocks"),$K55,"") | Q55: =IF($C55=Q$1,$K55,"") | R55: =IF($C55=Q$1,$F55,"") | S55: =IF($C55=S$1,$K55,"") | T55: =IF($C55=S$1,$F55,"") | U55: =IF($C55=U$1,$K55,"") | V55: =IF($C55=U$1,$F55,"") | W55: =IF($C55=W$1,$K55,"") | X55: =IF($C55=W$1,$F55,"") | Y55: =IF($C55=Y$1,$K55,"") | Z55: =IF($C55=Y$1,$F55,"") | AA55: =IF($C55=AA$1,$K55,"") | AB55: =IF($C55=AA$1,$F55,"") | AC55: =IF($C55=AC$1,$K55,"") | AD55: =IF($C55=AC$1,$F55,"") | AE55: =IF($C55=AE$1,$K55,"") | AF55: =IF($C55=AE$1,$F55,"") | AG55: =IF($C55=AG$1,$K55,"") | AH55: =IF($C55=AG$1,$F55,"") | AI55: =IF($C55=AI$1,$K55,"") | AJ55: =IF($C55=AI$1,$F55,"") | AK55: =IF($C55=AK$1,$K55,"") | AL55: =IF($C55=AK$1,$F55,"") | AM55: =IF($C55=AM$1,$K55,"") | AN55: =IF($C55=AM$1,$F55,"") | AO55: =IF($C55=AO$1,$K55,"") -> 20420.7 | AP55: =IF($C55=AO$1,$F55,"") -> 31.66 | AQ55: =IF($F55="",0,IF($D55=AQ$1,$F55,0)) -> 0 | AR55: =IF($D55=AQ$1,N($K55)-N($L55)-N($O55),0) -> 0 | AS55: =IF($F55="",0,IF($D55=AS$1,$F55,0)) -> 31.66 | AT55: =IF($D55=AS$1,N($K55)-N($L55)-N($O55),0) -> 1110.7 | AU55: =IF(N($J55)>0,N($F55),0) -> 31.66 | AV55: =IF(N($J55)>0,$F55*$J55,0) -> 633.2
A56: 45990 | B56: Rock | C56: Kochammini | D56: WO Pass | E56: =E55+1 -> 54 | F56: 32.58 | G56: 610 | H56: 645 | I56: 0 | J56: 20 | K56: =IF($F56="","",$F56*$H56) -> 21014.1 | L56: =IFERROR(ROUND($F56*$G56,-1),"") -> 19870 | N56: =IF($F56="","",IF(N($I56)>0,$F56,0)) -> 0 | O56: =IF($F56="","",N($N56)*N($I56)) -> 0 | P56: =IF(OR($C56=P$1,$C56="Titan Rocks"),$K56,"") | Q56: =IF($C56=Q$1,$K56,"") | R56: =IF($C56=Q$1,$F56,"") | S56: =IF($C56=S$1,$K56,"") | T56: =IF($C56=S$1,$F56,"") | U56: =IF($C56=U$1,$K56,"") | V56: =IF($C56=U$1,$F56,"") | W56: =IF($C56=W$1,$K56,"") | X56: =IF($C56=W$1,$F56,"") | Y56: =IF($C56=Y$1,$K56,"") | Z56: =IF($C56=Y$1,$F56,"") | AA56: =IF($C56=AA$1,$K56,"") | AB56: =IF($C56=AA$1,$F56,"") | AC56: =IF($C56=AC$1,$K56,"") | AD56: =IF($C56=AC$1,$F56,"") | AE56: =IF($C56=AE$1,$K56,"") | AF56: =IF($C56=AE$1,$F56,"") | AG56: =IF($C56=AG$1,$K56,"") | AH56: =IF($C56=AG$1,$F56,"") | AI56: =IF($C56=AI$1,$K56,"") | AJ56: =IF($C56=AI$1,$F56,"") | AK56: =IF($C56=AK$1,$K56,"") | AL56: =IF($C56=AK$1,$F56,"") | AM56: =IF($C56=AM$1,$K56,"") | AN56: =IF($C56=AM$1,$F56,"") | AO56: =IF($C56=AO$1,$K56,"") -> 21014.1 | AP56: =IF($C56=AO$1,$F56,"") -> 32.58 | AQ56: =IF($F56="",0,IF($D56=AQ$1,$F56,0)) -> 0 | AR56: =IF($D56=AQ$1,N($K56)-N($L56)-N($O56),0) -> 0 | AS56: =IF($F56="",0,IF($D56=AS$1,$F56,0)) -> 32.58 | AT56: =IF($D56=AS$1,N($K56)-N($L56)-N($O56),0) -> 1144.1 | AU56: =IF(N($J56)>0,N($F56),0) -> 32.58 | AV56: =IF(N($J56)>0,$F56*$J56,0) -> 651.6
A57: 45990 | B57: Rock | C57: Kochammini | D57: WO Pass | E57: =E56+1 -> 55 | F57: 32.81 | G57: 610 | H57: 645 | I57: 0 | J57: 20 | K57: =IF($F57="","",$F57*$H57) -> 21162.45 | L57: =IFERROR(ROUND($F57*$G57,-1),"") -> 20010 | N57: =IF($F57="","",IF(N($I57)>0,$F57,0)) -> 0 | O57: =IF($F57="","",N($N57)*N($I57)) -> 0 | P57: =IF(OR($C57=P$1,$C57="Titan Rocks"),$K57,"") | Q57: =IF($C57=Q$1,$K57,"") | R57: =IF($C57=Q$1,$F57,"") | S57: =IF($C57=S$1,$K57,"") | T57: =IF($C57=S$1,$F57,"") | U57: =IF($C57=U$1,$K57,"") | V57: =IF($C57=U$1,$F57,"") | W57: =IF($C57=W$1,$K57,"") | X57: =IF($C57=W$1,$F57,"") | Y57: =IF($C57=Y$1,$K57,"") | Z57: =IF($C57=Y$1,$F57,"") | AA57: =IF($C57=AA$1,$K57,"") | AB57: =IF($C57=AA$1,$F57,"") | AC57: =IF($C57=AC$1,$K57,"") | AD57: =IF($C57=AC$1,$F57,"") | AE57: =IF($C57=AE$1,$K57,"") | AF57: =IF($C57=AE$1,$F57,"") | AG57: =IF($C57=AG$1,$K57,"") | AH57: =IF($C57=AG$1,$F57,"") | AI57: =IF($C57=AI$1,$K57,"") | AJ57: =IF($C57=AI$1,$F57,"") | AK57: =IF($C57=AK$1,$K57,"") | AL57: =IF($C57=AK$1,$F57,"") | AM57: =IF($C57=AM$1,$K57,"") | AN57: =IF($C57=AM$1,$F57,"") | AO57: =IF($C57=AO$1,$K57,"") -> 21162.45 | AP57: =IF($C57=AO$1,$F57,"") -> 32.81 | AQ57: =IF($F57="",0,IF($D57=AQ$1,$F57,0)) -> 0 | AR57: =IF($D57=AQ$1,N($K57)-N($L57)-N($O57),0) -> 0 | AS57: =IF($F57="",0,IF($D57=AS$1,$F57,0)) -> 32.81 | AT57: =IF($D57=AS$1,N($K57)-N($L57)-N($O57),0) -> 1152.45 | AU57: =IF(N($J57)>0,N($F57),0) -> 32.81 | AV57: =IF(N($J57)>0,$F57*$J57,0) -> 656.2
A58: 45990 | B58: Rock | C58: MR Granites | D58: WO Pass | E58: =E57+1 -> 56 | F58: 33.5 | G58: 610 | H58: 875 | I58: 220 | J58: 20 | K58: =IF($F58="","",$F58*$H58) -> 29312.5 | L58: =IFERROR(ROUND($F58*$G58,-1),"") -> 20440 | M58: KL 02 BG 3968 | N58: =IF($F58="","",IF(N($I58)>0,$F58,0)) -> 33.5 | O58: =IF($F58="","",N($N58)*N($I58)) -> 7370 | P58: =IF(OR($C58=P$1,$C58="Titan Rocks"),$K58,"") | Q58: =IF($C58=Q$1,$K58,"") -> 29312.5 | R58: =IF($C58=Q$1,$F58,"") -> 33.5 | S58: =IF($C58=S$1,$K58,"") | T58: =IF($C58=S$1,$F58,"") | U58: =IF($C58=U$1,$K58,"") | V58: =IF($C58=U$1,$F58,"") | W58: =IF($C58=W$1,$K58,"") | X58: =IF($C58=W$1,$F58,"") | Y58: =IF($C58=Y$1,$K58,"") | Z58: =IF($C58=Y$1,$F58,"") | AA58: =IF($C58=AA$1,$K58,"") | AB58: =IF($C58=AA$1,$F58,"") | AC58: =IF($C58=AC$1,$K58,"") | AD58: =IF($C58=AC$1,$F58,"") | AE58: =IF($C58=AE$1,$K58,"") | AF58: =IF($C58=AE$1,$F58,"") | AG58: =IF($C58=AG$1,$K58,"") | AH58: =IF($C58=AG$1,$F58,"") | AI58: =IF($C58=AI$1,$K58,"") | AJ58: =IF($C58=AI$1,$F58,"") | AK58: =IF($C58=AK$1,$K58,"") | AL58: =IF($C58=AK$1,$F58,"") | AM58: =IF($C58=AM$1,$K58,"") | AN58: =IF($C58=AM$1,$F58,"") | AO58: =IF($C58=AO$1,$K58,"") | AP58: =IF($C58=AO$1,$F58,"") | AQ58: =IF($F58="",0,IF($D58=AQ$1,$F58,0)) -> 0 | AR58: =IF($D58=AQ$1,N($K58)-N($L58)-N($O58),0) -> 0 | AS58: =IF($F58="",0,IF($D58=AS$1,$F58,0)) -> 33.5 | AT58: =IF($D58=AS$1,N($K58)-N($L58)-N($O58),0) -> 1502.5 | AU58: =IF(N($J58)>0,N($F58),0) -> 33.5 | AV58: =IF(N($J58)>0,$F58*$J58,0) -> 670
A59: 45990 | B59: Rock | C59: MR Granites | D59: WO Pass | E59: =E58+1 -> 57 | F59: 32.65 | G59: 610 | H59: 875 | I59: 220 | J59: 20 | K59: =IF($F59="","",$F59*$H59) -> 28568.75 | L59: =IFERROR(ROUND($F59*$G59,-1),"") -> 19920 | M59: KL 21 U 5340 | N59: =IF($F59="","",IF(N($I59)>0,$F59,0)) -> 32.65 | O59: =IF($F59="","",N($N59)*N($I59)) -> 7183 | P59: =IF(OR($C59=P$1,$C59="Titan Rocks"),$K59,"") | Q59: =IF($C59=Q$1,$K59,"") -> 28568.75 | R59: =IF($C59=Q$1,$F59,"") -> 32.65 | S59: =IF($C59=S$1,$K59,"") | T59: =IF($C59=S$1,$F59,"") | U59: =IF($C59=U$1,$K59,"") | V59: =IF($C59=U$1,$F59,"") | W59: =IF($C59=W$1,$K59,"") | X59: =IF($C59=W$1,$F59,"") | Y59: =IF($C59=Y$1,$K59,"") | Z59: =IF($C59=Y$1,$F59,"") | AA59: =IF($C59=AA$1,$K59,"") | AB59: =IF($C59=AA$1,$F59,"") | AC59: =IF($C59=AC$1,$K59,"") | AD59: =IF($C59=AC$1,$F59,"") | AE59: =IF($C59=AE$1,$K59,"") | AF59: =IF($C59=AE$1,$F59,"") | AG59: =IF($C59=AG$1,$K59,"") | AH59: =IF($C59=AG$1,$F59,"") | AI59: =IF($C59=AI$1,$K59,"") | AJ59: =IF($C59=AI$1,$F59,"") | AK59: =IF($C59=AK$1,$K59,"") | AL59: =IF($C59=AK$1,$F59,"") | AM59: =IF($C59=AM$1,$K59,"") | AN59: =IF($C59=AM$1,$F59,"") | AO59: =IF($C59=AO$1,$K59,"") | AP59: =IF($C59=AO$1,$F59,"") | AQ59: =IF($F59="",0,IF($D59=AQ$1,$F59,0)) -> 0 | AR59: =IF($D59=AQ$1,N($K59)-N($L59)-N($O59),0) -> 0 | AS59: =IF($F59="",0,IF($D59=AS$1,$F59,0)) -> 32.65 | AT59: =IF($D59=AS$1,N($K59)-N($L59)-N($O59),0) -> 1465.75 | AU59: =IF(N($J59)>0,N($F59),0) -> 32.65 | AV59: =IF(N($J59)>0,$F59*$J59,0) -> 653
A60: 45990 | B60: Rock | C60: Outside site No Profit | E60: =E59+1 -> 58 | F60: 26.92 | G60: 700 | H60: 700 | K60: =IF($F60="","",$F60*$H60) -> 18844 | L60: =IFERROR(ROUND($F60*$G60,-1),"") -> 18840 | N60: =IF($F60="","",IF(N($I60)>0,$F60,0)) -> 0 | O60: =IF($F60="","",N($N60)*N($I60)) -> 0 | P60: =IF(OR($C60=P$1,$C60="Titan Rocks"),$K60,"") -> 18844 | Q60: =IF($C60=Q$1,$K60,"") | R60: =IF($C60=Q$1,$F60,"") | S60: =IF($C60=S$1,$K60,"") | T60: =IF($C60=S$1,$F60,"") | U60: =IF($C60=U$1,$K60,"") | V60: =IF($C60=U$1,$F60,"") | W60: =IF($C60=W$1,$K60,"") | X60: =IF($C60=W$1,$F60,"") | Y60: =IF($C60=Y$1,$K60,"") | Z60: =IF($C60=Y$1,$F60,"") | AA60: =IF($C60=AA$1,$K60,"") | AB60: =IF($C60=AA$1,$F60,"") | AC60: =IF($C60=AC$1,$K60,"") | AD60: =IF($C60=AC$1,$F60,"") | AE60: =IF($C60=AE$1,$K60,"") | AF60: =IF($C60=AE$1,$F60,"") | AG60: =IF($C60=AG$1,$K60,"") | AH60: =IF($C60=AG$1,$F60,"") | AI60: =IF($C60=AI$1,$K60,"") | AJ60: =IF($C60=AI$1,$F60,"") | AK60: =IF($C60=AK$1,$K60,"") | AL60: =IF($C60=AK$1,$F60,"") | AM60: =IF($C60=AM$1,$K60,"") | AN60: =IF($C60=AM$1,$F60,"") | AO60: =IF($C60=AO$1,$K60,"") | AP60: =IF($C60=AO$1,$F60,"") | AQ60: =IF($F60="",0,IF($D60=AQ$1,$F60,0)) -> 0 | AR60: =IF($D60=AQ$1,N($K60)-N($L60)-N($O60),0) -> 0 | AS60: =IF($F60="",0,IF($D60=AS$1,$F60,0)) -> 0 | AT60: =IF($D60=AS$1,N($K60)-N($L60)-N($O60),0) -> 0 | AU60: =IF(N($J60)>0,N($F60),0) -> 0 | AV60: =IF(N($J60)>0,$F60*$J60,0) -> 0
A61: 46087 | B61: Rock | C61: AVK | D61: WO Pass | E61: =E60+1 -> 59 | F61: 32.82 | G61: 610 | H61: 900 | I61: 250 | J61: 20 | K61: =IF($F61="","",$F61*$H61) -> 29538 | L61: =IFERROR(ROUND($F61*$G61,-1),"") -> 20020 | M61: KL 40 Q 3885 | N61: =IF($F61="","",IF(N($I61)>0,$F61,0)) -> 32.82 | O61: =IF($F61="","",N($N61)*N($I61)) -> 8205 | P61: =IF(OR($C61=P$1,$C61="Titan Rocks"),$K61,"") | Q61: =IF($C61=Q$1,$K61,"") | R61: =IF($C61=Q$1,$F61,"") | S61: =IF($C61=S$1,$K61,"") -> 29538 | T61: =IF($C61=S$1,$F61,"") -> 32.82 | U61: =IF($C61=U$1,$K61,"") | V61: =IF($C61=U$1,$F61,"") | W61: =IF($C61=W$1,$K61,"") | X61: =IF($C61=W$1,$F61,"") | Y61: =IF($C61=Y$1,$K61,"") | Z61: =IF($C61=Y$1,$F61,"") | AA61: =IF($C61=AA$1,$K61,"") | AB61: =IF($C61=AA$1,$F61,"") | AC61: =IF($C61=AC$1,$K61,"") | AD61: =IF($C61=AC$1,$F61,"") | AE61: =IF($C61=AE$1,$K61,"") | AF61: =IF($C61=AE$1,$F61,"") | AG61: =IF($C61=AG$1,$K61,"") | AH61: =IF($C61=AG$1,$F61,"") | AI61: =IF($C61=AI$1,$K61,"") | AJ61: =IF($C61=AI$1,$F61,"") | AK61: =IF($C61=AK$1,$K61,"") | AL61: =IF($C61=AK$1,$F61,"") | AM61: =IF($C61=AM$1,$K61,"") | AN61: =IF($C61=AM$1,$F61,"") | AO61: =IF($C61=AO$1,$K61,"") | AP61: =IF($C61=AO$1,$F61,"") | AQ61: =IF($F61="",0,IF($D61=AQ$1,$F61,0)) -> 0 | AR61: =IF($D61=AQ$1,N($K61)-N($L61)-N($O61),0) -> 0 | AS61: =IF($F61="",0,IF($D61=AS$1,$F61,0)) -> 32.82 | AT61: =IF($D61=AS$1,N($K61)-N($L61)-N($O61),0) -> 1313 | AU61: =IF(N($J61)>0,N($F61),0) -> 32.82 | AV61: =IF(N($J61)>0,$F61*$J61,0) -> 656.4
A62: 46087 | B62: Rock | C62: Kochammini | D62: Pass | E62: =E61+1 -> 60 | F62: 29.74 | G62: 640 | H62: 645 | I62: 0 | J62: 20 | K62: =IF($F62="","",$F62*$H62) -> 19182.3 | L62: =IFERROR(ROUND($F62*$G62,-1),"") -> 19030 | N62: =IF($F62="","",IF(N($I62)>0,$F62,0)) -> 0 | O62: =IF($F62="","",N($N62)*N($I62)) -> 0 | P62: =IF(OR($C62=P$1,$C62="Titan Rocks"),$K62,"") | Q62: =IF($C62=Q$1,$K62,"") | R62: =IF($C62=Q$1,$F62,"") | S62: =IF($C62=S$1,$K62,"") | T62: =IF($C62=S$1,$F62,"") | U62: =IF($C62=U$1,$K62,"") | V62: =IF($C62=U$1,$F62,"") | W62: =IF($C62=W$1,$K62,"") | X62: =IF($C62=W$1,$F62,"") | Y62: =IF($C62=Y$1,$K62,"") | Z62: =IF($C62=Y$1,$F62,"") | AA62: =IF($C62=AA$1,$K62,"") | AB62: =IF($C62=AA$1,$F62,"") | AC62: =IF($C62=AC$1,$K62,"") | AD62: =IF($C62=AC$1,$F62,"") | AE62: =IF($C62=AE$1,$K62,"") | AF62: =IF($C62=AE$1,$F62,"") | AG62: =IF($C62=AG$1,$K62,"") | AH62: =IF($C62=AG$1,$F62,"") | AI62: =IF($C62=AI$1,$K62,"") | AJ62: =IF($C62=AI$1,$F62,"") | AK62: =IF($C62=AK$1,$K62,"") | AL62: =IF($C62=AK$1,$F62,"") | AM62: =IF($C62=AM$1,$K62,"") | AN62: =IF($C62=AM$1,$F62,"") | AO62: =IF($C62=AO$1,$K62,"") -> 19182.3 | AP62: =IF($C62=AO$1,$F62,"") -> 29.74 | AQ62: =IF($F62="",0,IF($D62=AQ$1,$F62,0)) -> 29.74 | AR62: =IF($D62=AQ$1,N($K62)-N($L62)-N($O62),0) -> 152.3 | AS62: =IF($F62="",0,IF($D62=AS$1,$F62,0)) -> 0 | AT62: =IF($D62=AS$1,N($K62)-N($L62)-N($O62),0) -> 0 | AU62: =IF(N($J62)>0,N($F62),0) -> 29.74 | AV62: =IF(N($J62)>0,$F62*$J62,0) -> 594.8
A63: 46087 | B63: Rock | C63: Kochammini | D63: WO Pass | E63: =E62+1 -> 61 | F63: 17.43 | G63: 610 | H63: 645 | I63: 0 | J63: 20 | K63: =IF($F63="","",$F63*$H63) -> 11242.35 | L63: =IFERROR(ROUND($F63*$G63,-1),"") -> 10630 | N63: =IF($F63="","",IF(N($I63)>0,$F63,0)) -> 0 | O63: =IF($F63="","",N($N63)*N($I63)) -> 0 | P63: =IF(OR($C63=P$1,$C63="Titan Rocks"),$K63,"") | Q63: =IF($C63=Q$1,$K63,"") | R63: =IF($C63=Q$1,$F63,"") | S63: =IF($C63=S$1,$K63,"") | T63: =IF($C63=S$1,$F63,"") | U63: =IF($C63=U$1,$K63,"") | V63: =IF($C63=U$1,$F63,"") | W63: =IF($C63=W$1,$K63,"") | X63: =IF($C63=W$1,$F63,"") | Y63: =IF($C63=Y$1,$K63,"") | Z63: =IF($C63=Y$1,$F63,"") | AA63: =IF($C63=AA$1,$K63,"") | AB63: =IF($C63=AA$1,$F63,"") | AC63: =IF($C63=AC$1,$K63,"") | AD63: =IF($C63=AC$1,$F63,"") | AE63: =IF($C63=AE$1,$K63,"") | AF63: =IF($C63=AE$1,$F63,"") | AG63: =IF($C63=AG$1,$K63,"") | AH63: =IF($C63=AG$1,$F63,"") | AI63: =IF($C63=AI$1,$K63,"") | AJ63: =IF($C63=AI$1,$F63,"") | AK63: =IF($C63=AK$1,$K63,"") | AL63: =IF($C63=AK$1,$F63,"") | AM63: =IF($C63=AM$1,$K63,"") | AN63: =IF($C63=AM$1,$F63,"") | AO63: =IF($C63=AO$1,$K63,"") -> 11242.35 | AP63: =IF($C63=AO$1,$F63,"") -> 17.43 | AQ63: =IF($F63="",0,IF($D63=AQ$1,$F63,0)) -> 0 | AR63: =IF($D63=AQ$1,N($K63)-N($L63)-N($O63),0) -> 0 | AS63: =IF($F63="",0,IF($D63=AS$1,$F63,0)) -> 17.43 | AT63: =IF($D63=AS$1,N($K63)-N($L63)-N($O63),0) -> 612.35 | AU63: =IF(N($J63)>0,N($F63),0) -> 17.43 | AV63: =IF(N($J63)>0,$F63*$J63,0) -> 348.6
A64: 46087 | B64: Rock | C64: Kochammini | D64: WO Pass | E64: =E63+1 -> 62 | F64: 21.78 | G64: 610 | H64: 645 | I64: 0 | J64: 20 | K64: =IF($F64="","",$F64*$H64) -> 14048.1 | L64: =IFERROR(ROUND($F64*$G64,-1),"") -> 13290 | N64: =IF($F64="","",IF(N($I64)>0,$F64,0)) -> 0 | O64: =IF($F64="","",N($N64)*N($I64)) -> 0 | P64: =IF(OR($C64=P$1,$C64="Titan Rocks"),$K64,"") | Q64: =IF($C64=Q$1,$K64,"") | R64: =IF($C64=Q$1,$F64,"") | S64: =IF($C64=S$1,$K64,"") | T64: =IF($C64=S$1,$F64,"") | U64: =IF($C64=U$1,$K64,"") | V64: =IF($C64=U$1,$F64,"") | W64: =IF($C64=W$1,$K64,"") | X64: =IF($C64=W$1,$F64,"") | Y64: =IF($C64=Y$1,$K64,"") | Z64: =IF($C64=Y$1,$F64,"") | AA64: =IF($C64=AA$1,$K64,"") | AB64: =IF($C64=AA$1,$F64,"") | AC64: =IF($C64=AC$1,$K64,"") | AD64: =IF($C64=AC$1,$F64,"") | AE64: =IF($C64=AE$1,$K64,"") | AF64: =IF($C64=AE$1,$F64,"") | AG64: =IF($C64=AG$1,$K64,"") | AH64: =IF($C64=AG$1,$F64,"") | AI64: =IF($C64=AI$1,$K64,"") | AJ64: =IF($C64=AI$1,$F64,"") | AK64: =IF($C64=AK$1,$K64,"") | AL64: =IF($C64=AK$1,$F64,"") | AM64: =IF($C64=AM$1,$K64,"") | AN64: =IF($C64=AM$1,$F64,"") | AO64: =IF($C64=AO$1,$K64,"") -> 14048.1 | AP64: =IF($C64=AO$1,$F64,"") -> 21.78 | AQ64: =IF($F64="",0,IF($D64=AQ$1,$F64,0)) -> 0 | AR64: =IF($D64=AQ$1,N($K64)-N($L64)-N($O64),0) -> 0 | AS64: =IF($F64="",0,IF($D64=AS$1,$F64,0)) -> 21.78 | AT64: =IF($D64=AS$1,N($K64)-N($L64)-N($O64),0) -> 758.1 | AU64: =IF(N($J64)>0,N($F64),0) -> 21.78 | AV64: =IF(N($J64)>0,$F64*$J64,0) -> 435.6
A65: 46087 | B65: Rock | C65: Kochammini | D65: Pass | E65: =E64+1 -> 63 | F65: 20.65 | G65: 640 | H65: 645 | I65: 0 | J65: 20 | K65: =IF($F65="","",$F65*$H65) -> 13319.25 | L65: =IFERROR(ROUND($F65*$G65,-1),"") -> 13220 | N65: =IF($F65="","",IF(N($I65)>0,$F65,0)) -> 0 | O65: =IF($F65="","",N($N65)*N($I65)) -> 0 | P65: =IF(OR($C65=P$1,$C65="Titan Rocks"),$K65,"") | Q65: =IF($C65=Q$1,$K65,"") | R65: =IF($C65=Q$1,$F65,"") | S65: =IF($C65=S$1,$K65,"") | T65: =IF($C65=S$1,$F65,"") | U65: =IF($C65=U$1,$K65,"") | V65: =IF($C65=U$1,$F65,"") | W65: =IF($C65=W$1,$K65,"") | X65: =IF($C65=W$1,$F65,"") | Y65: =IF($C65=Y$1,$K65,"") | Z65: =IF($C65=Y$1,$F65,"") | AA65: =IF($C65=AA$1,$K65,"") | AB65: =IF($C65=AA$1,$F65,"") | AC65: =IF($C65=AC$1,$K65,"") | AD65: =IF($C65=AC$1,$F65,"") | AE65: =IF($C65=AE$1,$K65,"") | AF65: =IF($C65=AE$1,$F65,"") | AG65: =IF($C65=AG$1,$K65,"") | AH65: =IF($C65=AG$1,$F65,"") | AI65: =IF($C65=AI$1,$K65,"") | AJ65: =IF($C65=AI$1,$F65,"") | AK65: =IF($C65=AK$1,$K65,"") | AL65: =IF($C65=AK$1,$F65,"") | AM65: =IF($C65=AM$1,$K65,"") | AN65: =IF($C65=AM$1,$F65,"") | AO65: =IF($C65=AO$1,$K65,"") -> 13319.25 | AP65: =IF($C65=AO$1,$F65,"") -> 20.65 | AQ65: =IF($F65="",0,IF($D65=AQ$1,$F65,0)) -> 20.65 | AR65: =IF($D65=AQ$1,N($K65)-N($L65)-N($O65),0) -> 99.25 | AS65: =IF($F65="",0,IF($D65=AS$1,$F65,0)) -> 0 | AT65: =IF($D65=AS$1,N($K65)-N($L65)-N($O65),0) -> 0 | AU65: =IF(N($J65)>0,N($F65),0) -> 20.65 | AV65: =IF(N($J65)>0,$F65*$J65,0) -> 413
A66: 46087 | B66: Rock | C66: Kochammini | D66: Pass | E66: =E65+1 -> 64 | F66: 31.89 | G66: 640 | H66: 645 | I66: 0 | J66: 20 | K66: =IF($F66="","",$F66*$H66) -> 20569.05 | L66: =IFERROR(ROUND($F66*$G66,-1),"") -> 20410 | N66: =IF($F66="","",IF(N($I66)>0,$F66,0)) -> 0 | O66: =IF($F66="","",N($N66)*N($I66)) -> 0 | P66: =IF(OR($C66=P$1,$C66="Titan Rocks"),$K66,"") | Q66: =IF($C66=Q$1,$K66,"") | R66: =IF($C66=Q$1,$F66,"") | S66: =IF($C66=S$1,$K66,"") | T66: =IF($C66=S$1,$F66,"") | U66: =IF($C66=U$1,$K66,"") | V66: =IF($C66=U$1,$F66,"") | W66: =IF($C66=W$1,$K66,"") | X66: =IF($C66=W$1,$F66,"") | Y66: =IF($C66=Y$1,$K66,"") | Z66: =IF($C66=Y$1,$F66,"") | AA66: =IF($C66=AA$1,$K66,"") | AB66: =IF($C66=AA$1,$F66,"") | AC66: =IF($C66=AC$1,$K66,"") | AD66: =IF($C66=AC$1,$F66,"") | AE66: =IF($C66=AE$1,$K66,"") | AF66: =IF($C66=AE$1,$F66,"") | AG66: =IF($C66=AG$1,$K66,"") | AH66: =IF($C66=AG$1,$F66,"") | AI66: =IF($C66=AI$1,$K66,"") | AJ66: =IF($C66=AI$1,$F66,"") | AK66: =IF($C66=AK$1,$K66,"") | AL66: =IF($C66=AK$1,$F66,"") | AM66: =IF($C66=AM$1,$K66,"") | AN66: =IF($C66=AM$1,$F66,"") | AO66: =IF($C66=AO$1,$K66,"") -> 20569.05 | AP66: =IF($C66=AO$1,$F66,"") -> 31.89 | AQ66: =IF($F66="",0,IF($D66=AQ$1,$F66,0)) -> 31.89 | AR66: =IF($D66=AQ$1,N($K66)-N($L66)-N($O66),0) -> 159.05 | AS66: =IF($F66="",0,IF($D66=AS$1,$F66,0)) -> 0 | AT66: =IF($D66=AS$1,N($K66)-N($L66)-N($O66),0) -> 0 | AU66: =IF(N($J66)>0,N($F66),0) -> 31.89 | AV66: =IF(N($J66)>0,$F66*$J66,0) -> 637.8
A67: 46087 | B67: Rock | C67: Kochammini | D67: WO Pass | E67: =E66+1 -> 65 | F67: 30.75 | G67: 610 | H67: 645 | I67: 0 | J67: 20 | K67: =IF($F67="","",$F67*$H67) -> 19833.75 | L67: =IFERROR(ROUND($F67*$G67,-1),"") -> 18760 | N67: =IF($F67="","",IF(N($I67)>0,$F67,0)) -> 0 | O67: =IF($F67="","",N($N67)*N($I67)) -> 0 | P67: =IF(OR($C67=P$1,$C67="Titan Rocks"),$K67,"") | Q67: =IF($C67=Q$1,$K67,"") | R67: =IF($C67=Q$1,$F67,"") | S67: =IF($C67=S$1,$K67,"") | T67: =IF($C67=S$1,$F67,"") | U67: =IF($C67=U$1,$K67,"") | V67: =IF($C67=U$1,$F67,"") | W67: =IF($C67=W$1,$K67,"") | X67: =IF($C67=W$1,$F67,"") | Y67: =IF($C67=Y$1,$K67,"") | Z67: =IF($C67=Y$1,$F67,"") | AA67: =IF($C67=AA$1,$K67,"") | AB67: =IF($C67=AA$1,$F67,"") | AC67: =IF($C67=AC$1,$K67,"") | AD67: =IF($C67=AC$1,$F67,"") | AE67: =IF($C67=AE$1,$K67,"") | AF67: =IF($C67=AE$1,$F67,"") | AG67: =IF($C67=AG$1,$K67,"") | AH67: =IF($C67=AG$1,$F67,"") | AI67: =IF($C67=AI$1,$K67,"") | AJ67: =IF($C67=AI$1,$F67,"") | AK67: =IF($C67=AK$1,$K67,"") | AL67: =IF($C67=AK$1,$F67,"") | AM67: =IF($C67=AM$1,$K67,"") | AN67: =IF($C67=AM$1,$F67,"") | AO67: =IF($C67=AO$1,$K67,"") -> 19833.75 | AP67: =IF($C67=AO$1,$F67,"") -> 30.75 | AQ67: =IF($F67="",0,IF($D67=AQ$1,$F67,0)) -> 0 | AR67: =IF($D67=AQ$1,N($K67)-N($L67)-N($O67),0) -> 0 | AS67: =IF($F67="",0,IF($D67=AS$1,$F67,0)) -> 30.75 | AT67: =IF($D67=AS$1,N($K67)-N($L67)-N($O67),0) -> 1073.75 | AU67: =IF(N($J67)>0,N($F67),0) -> 30.75 | AV67: =IF(N($J67)>0,$F67*$J67,0) -> 615
A68: 46087 | B68: Rock | C68: AVK | D68: Pass | E68: =E67+1 -> 66 | F68: 32.92 | G68: 640 | H68: 900 | I68: 250 | J68: 20 | K68: =IF($F68="","",$F68*$H68) -> 29628 | L68: =IFERROR(ROUND($F68*$G68,-1),"") -> 21070 | M68: KL 40 Q 3885 | N68: =IF($F68="","",IF(N($I68)>0,$F68,0)) -> 32.92 | O68: =IF($F68="","",N($N68)*N($I68)) -> 8230 | P68: =IF(OR($C68=P$1,$C68="Titan Rocks"),$K68,"") | Q68: =IF($C68=Q$1,$K68,"") | R68: =IF($C68=Q$1,$F68,"") | S68: =IF($C68=S$1,$K68,"") -> 29628 | T68: =IF($C68=S$1,$F68,"") -> 32.92 | U68: =IF($C68=U$1,$K68,"") | V68: =IF($C68=U$1,$F68,"") | W68: =IF($C68=W$1,$K68,"") | X68: =IF($C68=W$1,$F68,"") | Y68: =IF($C68=Y$1,$K68,"") | Z68: =IF($C68=Y$1,$F68,"") | AA68: =IF($C68=AA$1,$K68,"") | AB68: =IF($C68=AA$1,$F68,"") | AC68: =IF($C68=AC$1,$K68,"") | AD68: =IF($C68=AC$1,$F68,"") | AE68: =IF($C68=AE$1,$K68,"") | AF68: =IF($C68=AE$1,$F68,"") | AG68: =IF($C68=AG$1,$K68,"") | AH68: =IF($C68=AG$1,$F68,"") | AI68: =IF($C68=AI$1,$K68,"") | AJ68: =IF($C68=AI$1,$F68,"") | AK68: =IF($C68=AK$1,$K68,"") | AL68: =IF($C68=AK$1,$F68,"") | AM68: =IF($C68=AM$1,$K68,"") | AN68: =IF($C68=AM$1,$F68,"") | AO68: =IF($C68=AO$1,$K68,"") | AP68: =IF($C68=AO$1,$F68,"") | AQ68: =IF($F68="",0,IF($D68=AQ$1,$F68,0)) -> 32.92 | AR68: =IF($D68=AQ$1,N($K68)-N($L68)-N($O68),0) -> 328 | AS68: =IF($F68="",0,IF($D68=AS$1,$F68,0)) -> 0 | AT68: =IF($D68=AS$1,N($K68)-N($L68)-N($O68),0) -> 0 | AU68: =IF(N($J68)>0,N($F68),0) -> 32.92 | AV68: =IF(N($J68)>0,$F68*$J68,0) -> 658.4
A69: 46087 | B69: Rock | C69: Kochammini | D69: WO Pass | E69: =E68+1 -> 67 | F69: 30.11 | G69: 610 | H69: 645 | I69: 0 | J69: 20 | K69: =IF($F69="","",$F69*$H69) -> 19420.95 | L69: =IFERROR(ROUND($F69*$G69,-1),"") -> 18370 | N69: =IF($F69="","",IF(N($I69)>0,$F69,0)) -> 0 | O69: =IF($F69="","",N($N69)*N($I69)) -> 0 | P69: =IF(OR($C69=P$1,$C69="Titan Rocks"),$K69,"") | Q69: =IF($C69=Q$1,$K69,"") | R69: =IF($C69=Q$1,$F69,"") | S69: =IF($C69=S$1,$K69,"") | T69: =IF($C69=S$1,$F69,"") | U69: =IF($C69=U$1,$K69,"") | V69: =IF($C69=U$1,$F69,"") | W69: =IF($C69=W$1,$K69,"") | X69: =IF($C69=W$1,$F69,"") | Y69: =IF($C69=Y$1,$K69,"") | Z69: =IF($C69=Y$1,$F69,"") | AA69: =IF($C69=AA$1,$K69,"") | AB69: =IF($C69=AA$1,$F69,"") | AC69: =IF($C69=AC$1,$K69,"") | AD69: =IF($C69=AC$1,$F69,"") | AE69: =IF($C69=AE$1,$K69,"") | AF69: =IF($C69=AE$1,$F69,"") | AG69: =IF($C69=AG$1,$K69,"") | AH69: =IF($C69=AG$1,$F69,"") | AI69: =IF($C69=AI$1,$K69,"") | AJ69: =IF($C69=AI$1,$F69,"") | AK69: =IF($C69=AK$1,$K69,"") | AL69: =IF($C69=AK$1,$F69,"") | AM69: =IF($C69=AM$1,$K69,"") | AN69: =IF($C69=AM$1,$F69,"") | AO69: =IF($C69=AO$1,$K69,"") -> 19420.95 | AP69: =IF($C69=AO$1,$F69,"") -> 30.11 | AQ69: =IF($F69="",0,IF($D69=AQ$1,$F69,0)) -> 0 | AR69: =IF($D69=AQ$1,N($K69)-N($L69)-N($O69),0) -> 0 | AS69: =IF($F69="",0,IF($D69=AS$1,$F69,0)) -> 30.11 | AT69: =IF($D69=AS$1,N($K69)-N($L69)-N($O69),0) -> 1050.95 | AU69: =IF(N($J69)>0,N($F69),0) -> 30.11 | AV69: =IF(N($J69)>0,$F69*$J69,0) -> 602.2
